Workbook

Sheet  AZUL 2
A7: AZUL PERIODO REGULAR 2026
A8: ORDEN DE COMPRA
A9: FECHA:
A10: FRUTAS Y VERDURAS:
A11: PROVEEDOR: FERNANDEZ ( LA PUNTUAL)
B12: EP 1 | C12: EP 7 | D12: EP 9 | E12: EP 13 | F12: EP 14 | G12: EP 16 | H12: EP 17 | I12: EP 18 | J12: EP 19 | K12: EP 21 | L12: EP 22 | M12: EP24 JIR7 | N12: EP25 JIR 4
B13: 94 | C13: 101 | D13: 6 | E13: 164 | F13: 90 | G13: 28 | H13: 27 | I13: 71 | J13: 148 | K13: 86 | L13: 92 | M13: 13 | N13: 22
B14: 47 | C14: 0 | D14: 3 | E14: 82 | F14: 0 | G14: 14 | H14: 0 | I14: 0 | J14: 87 | K14: 43 | L14: 56 | M14: 0 | N14: 10 | P14: PRECIO | Q14: PESOS X PRODUCTO
A15: MANZANA | B15: =PRODUCT(SEMANAL!$D6,B$13)/1000+PRODUCT(SEMANAL!$B6,B$14)/1000 -> 17.39 | C15: =PRODUCT(SEMANAL!$D6,C$13)/1000+PRODUCT(SEMANAL!$B6,C$14)/1000 -> 12.625 | D15: =PRODUCT(SEMANAL!$D6,D$13)/1000+PRODUCT(SEMANAL!$B6,D$14)/1000 -> 1.11 | E15: =PRODUCT(SEMANAL!$D6,E$13)/1000+PRODUCT(SEMANAL!$B6,E$14)/1000 -> 30.34 | F15: =PRODUCT(SEMANAL!$D6,F$13)/1000+PRODUCT(SEMANAL!$B6,F$14)/1000 -> 11.25 | G15: =PRODUCT(SEMANAL!$D6,G$13)/1000+PRODUCT(SEMANAL!$B6,G$14)/1000 -> 5.18 | H15: =PRODUCT(SEMANAL!$D6,H$13)/1000+PRODUCT(SEMANAL!$B6,H$14)/1000 -> 3.375 | I15: =PRODUCT(SEMANAL!$D6,I$13)/1000+PRODUCT(SEMANAL!$B6,I$14)/1000 -> 8.875 | ... N15: =PRODUCT(SEMANAL!$D6,N$13)/1000+PRODUCT(SEMANAL!$B6,N$14)/1000 -> 3.95 | O15: =SUM('OC FRUT y VERD AZUL 2'!B15:N15) -> 147 | P15: 2390 | Q15: =O15*P15 -> 351330
A16: BANANA | B16: =PRODUCT(SEMANAL!$D$7,B$13)/1000+PRODUCT(SEMANAL!$B$7,B$14)/1000 -> 5.64 | C16: =PRODUCT(SEMANAL!$D$7,C$13)/1000+PRODUCT(SEMANAL!$B$7,C$14)/1000 -> 0 | D16: =PRODUCT(SEMANAL!$D$7,D$13)/1000+PRODUCT(SEMANAL!$B$7,D$14)/1000 -> 0.36 | E16: =PRODUCT(SEMANAL!$D$7,E$13)/1000+PRODUCT(SEMANAL!$B$7,E$14)/1000 -> 9.84 | F16: =PRODUCT(SEMANAL!$D$7,F$13)/1000+PRODUCT(SEMANAL!$B$7,F$14)/1000 -> 0 | G16: =PRODUCT(SEMANAL!$D$7,G$13)/1000+PRODUCT(SEMANAL!$B$7,G$14)/1000 -> 1.68 | H16: =PRODUCT(SEMANAL!$D$7,H$13)/1000+PRODUCT(SEMANAL!$B$7,H$14)/1000 -> 0 | I16: =PRODUCT(SEMANAL!$D$7,I$13)/1000+PRODUCT(SEMANAL!$B$7,I$14)/1000 -> 0 | ... N16: =PRODUCT(SEMANAL!$D$7,N$13)/1000+PRODUCT(SEMANAL!$B$7,N$14)/1000 -> 1.2 | O16: =SUM('OC FRUT y VERD AZUL 2'!B16:N16) -> 45 | P16: 2550 | Q16: =O16*P16 -> 114750
A17: NARANJA O MANDARINA | B17: =PRODUCT(SEMANAL!$D8,B$13)/1000+PRODUCT(SEMANAL!B$8,B$14)/1000 -> 34.78 | C17: =PRODUCT(SEMANAL!$D8,C$13)/1000+PRODUCT(SEMANAL!C$8,C$14)/1000 -> 25.25 | D17: =PRODUCT(SEMANAL!$D8,D$13)/1000+PRODUCT(SEMANAL!D$8,D$14)/1000 -> 2.25 | E17: =PRODUCT(SEMANAL!$D8,E$13)/1000+PRODUCT(SEMANAL!E$8,E$14)/1000 -> 61.5 | F17: =PRODUCT(SEMANAL!$D8,F$13)/1000+PRODUCT(SEMANAL!F$8,F$14)/1000 -> 22.5 | G17: =PRODUCT(SEMANAL!$D8,G$13)/1000+PRODUCT(SEMANAL!G$8,G$14)/1000 -> 10.5 | H17: =PRODUCT(SEMANAL!$D8,H$13)/1000+PRODUCT(SEMANAL!H$8,H$14)/1000 -> 6.75 | I17: =PRODUCT(SEMANAL!$D8,I$13)/1000+PRODUCT(SEMANAL!I$8,I$14)/1000 -> 17.75 | ... N17: =PRODUCT(SEMANAL!$D8,N$13)/1000+PRODUCT(SEMANAL!N$8,N$14)/1000 -> 5.51 | O17: =SUM('OC FRUT y VERD AZUL 2'!B17:N17) -> 279 | P17: 1710 | Q17: =O17*P17 -> 477090
A18: PERA | B18: =PRODUCT(SEMANAL!$D9,B$13)/1000+PRODUCT(SEMANAL!B$9,B$14)/1000 -> 0 | C18: =PRODUCT(SEMANAL!$D9,C$13)/1000+PRODUCT(SEMANAL!C$9,C$14)/1000 -> 0 | D18: =PRODUCT(SEMANAL!$D9,D$13)/1000+PRODUCT(SEMANAL!D$9,D$14)/1000 -> 0 | E18: =PRODUCT(SEMANAL!$D9,E$13)/1000+PRODUCT(SEMANAL!E$9,E$14)/1000 -> 0 | F18: =PRODUCT(SEMANAL!$D9,F$13)/1000+PRODUCT(SEMANAL!F$9,F$14)/1000 -> 0 | G18: =PRODUCT(SEMANAL!$D9,G$13)/1000+PRODUCT(SEMANAL!G$9,G$14)/1000 -> 0 | H18: =PRODUCT(SEMANAL!$D9,H$13)/1000+PRODUCT(SEMANAL!H$9,H$14)/1000 -> 0 | I18: =PRODUCT(SEMANAL!$D9,I$13)/1000+PRODUCT(SEMANAL!I$9,I$14)/1000 -> 0 | ... N18: =PRODUCT(SEMANAL!$D9,N$13)/1000+PRODUCT(SEMANAL!N$9,N$14)/1000 -> 0.01 | O18: =SUM('OC FRUT y VERD AZUL 2'!B18:N18) -> 2 | P18: 2200 | Q18: =O18*P18 -> 4400
A19: Zapallo ANCO | B19: =PRODUCT(SEMANAL!$D10,B$13)/1000+PRODUCT(SEMANAL!$B10,B$14)/1000 -> 6.58 | C19: =PRODUCT(SEMANAL!$D10,C$13)/1000+PRODUCT(SEMANAL!$B10,C$14)/1000 -> 0 | D19: =PRODUCT(SEMANAL!$D10,D$13)/1000+PRODUCT(SEMANAL!$B10,D$14)/1000 -> 0.42 | E19: =PRODUCT(SEMANAL!$D10,E$13)/1000+PRODUCT(SEMANAL!$B10,E$14)/1000 -> 11.48 | F19: =PRODUCT(SEMANAL!$D10,F$13)/1000+PRODUCT(SEMANAL!$B10,F$14)/1000 -> 0 | G19: =PRODUCT(SEMANAL!$D10,G$13)/1000+PRODUCT(SEMANAL!$B10,G$14)/1000 -> 1.96 | H19: =PRODUCT(SEMANAL!$D10,H$13)/1000+PRODUCT(SEMANAL!$B10,H$14)/1000 -> 0 | I19: =PRODUCT(SEMANAL!$D10,I$13)/1000+PRODUCT(SEMANAL!$B10,I$14)/1000 -> 0 | ... N19: =PRODUCT(SEMANAL!$D10,N$13)/1000+PRODUCT(SEMANAL!$B10,N$14)/1000 -> 1.4 | O19: =SUM('OC FRUT y VERD AZUL 2'!B19:N19) -> 49 | P19: 1350 | Q19: =O19*P19 -> 66150
A20: Zapallo verde | B20: =PRODUCT(SEMANAL!$D11,B$13)/1000+PRODUCT(SEMANAL!$B11,B$14)/1000 -> 2.35 | C20: =PRODUCT(SEMANAL!$D11,C$13)/1000+PRODUCT(SEMANAL!$B11,C$14)/1000 -> 0 | D20: =PRODUCT(SEMANAL!$D11,D$13)/1000+PRODUCT(SEMANAL!$B11,D$14)/1000 -> 0.15 | E20: =PRODUCT(SEMANAL!$D11,E$13)/1000+PRODUCT(SEMANAL!$B11,E$14)/1000 -> 4.1 | F20: =PRODUCT(SEMANAL!$D11,F$13)/1000+PRODUCT(SEMANAL!$B11,F$14)/1000 -> 0 | G20: =PRODUCT(SEMANAL!$D11,G$13)/1000+PRODUCT(SEMANAL!$B11,G$14)/1000 -> 0.7 | H20: =PRODUCT(SEMANAL!$D11,H$13)/1000+PRODUCT(SEMANAL!$B11,H$14)/1000 -> 0 | I20: =PRODUCT(SEMANAL!$D11,I$13)/1000+PRODUCT(SEMANAL!$B11,I$14)/1000 -> 0 | ... N20: =PRODUCT(SEMANAL!$D11,N$13)/1000+PRODUCT(SEMANAL!$B11,N$14)/1000 -> 0.5 | O20: =SUM('OC FRUT y VERD AZUL 2'!B20:N20) -> 21 | P20: 1950 | Q20: =O20*P20 -> 40950
A21: Papa | B21: =PRODUCT(SEMANAL!$D12,B$13)/1000+PRODUCT(SEMANAL!$B12,B$14)/1000 -> 9.4 | C21: =PRODUCT(SEMANAL!$D12,C$13)/1000+PRODUCT(SEMANAL!$B12,C$14)/1000 -> 0 | D21: =PRODUCT(SEMANAL!$D12,D$13)/1000+PRODUCT(SEMANAL!$B12,D$14)/1000 -> 0.6 | E21: =PRODUCT(SEMANAL!$D12,E$13)/1000+PRODUCT(SEMANAL!$B12,E$14)/1000 -> 16.4 | F21: =PRODUCT(SEMANAL!$D12,F$13)/1000+PRODUCT(SEMANAL!$B12,F$14)/1000 -> 0 | G21: =PRODUCT(SEMANAL!$D12,G$13)/1000+PRODUCT(SEMANAL!$B12,G$14)/1000 -> 2.8 | H21: =PRODUCT(SEMANAL!$D12,H$13)/1000+PRODUCT(SEMANAL!$B12,H$14)/1000 -> 0 | I21: =PRODUCT(SEMANAL!$D12,I$13)/1000+PRODUCT(SEMANAL!$B12,I$14)/1000 -> 0 | ... N21: =PRODUCT(SEMANAL!$D12,N$13)/1000+PRODUCT(SEMANAL!$B12,N$14)/1000 -> 2 | O21: =SUM('OC FRUT y VERD AZUL 2'!B21:N21) -> 72 | P21: 1090 | Q21: =O21*P21 -> 78480
A22: Cebolla | B22: =PRODUCT(SEMANAL!$D13,B$13)/1000+PRODUCT(SEMANAL!$B13,B$14)/1000 -> 3.525 | C22: =PRODUCT(SEMANAL!$D13,C$13)/1000+PRODUCT(SEMANAL!$B13,C$14)/1000 -> 0 | D22: =PRODUCT(SEMANAL!$D13,D$13)/1000+PRODUCT(SEMANAL!$B13,D$14)/1000 -> 0.225 | E22: =PRODUCT(SEMANAL!$D13,E$13)/1000+PRODUCT(SEMANAL!$B13,E$14)/1000 -> 6.15 | F22: =PRODUCT(SEMANAL!$D13,F$13)/1000+PRODUCT(SEMANAL!$B13,F$14)/1000 -> 0 | G22: =PRODUCT(SEMANAL!$D13,G$13)/1000+PRODUCT(SEMANAL!$B13,G$14)/1000 -> 1.05 | H22: =PRODUCT(SEMANAL!$D13,H$13)/1000+PRODUCT(SEMANAL!$B13,H$14)/1000 -> 0 | I22: =PRODUCT(SEMANAL!$D13,I$13)/1000+PRODUCT(SEMANAL!$B13,I$14)/1000 -> 0 | ... N22: =PRODUCT(SEMANAL!$D13,N$13)/1000+PRODUCT(SEMANAL!$B13,N$14)/1000 -> 0.75 | O22: =SUM('OC FRUT y VERD AZUL 2'!B22:N22) -> 31 | P22: 1090 | Q22: =O22*P22 -> 33790
A23: Zanahoria | B23: =PRODUCT(SEMANAL!$D14,B$13)/1000+PRODUCT(SEMANAL!$B14,B$14)/1000 -> 2.35 | C23: =PRODUCT(SEMANAL!$D14,C$13)/1000+PRODUCT(SEMANAL!$B14,C$14)/1000 -> 0 | D23: =PRODUCT(SEMANAL!$D14,D$13)/1000+PRODUCT(SEMANAL!$B14,D$14)/1000 -> 0.15 | E23: =PRODUCT(SEMANAL!$D14,E$13)/1000+PRODUCT(SEMANAL!$B14,E$14)/1000 -> 4.1 | F23: =PRODUCT(SEMANAL!$D14,F$13)/1000+PRODUCT(SEMANAL!$B14,F$14)/1000 -> 0 | G23: =PRODUCT(SEMANAL!$D14,G$13)/1000+PRODUCT(SEMANAL!$B14,G$14)/1000 -> 0.7 | H23: =PRODUCT(SEMANAL!$D14,H$13)/1000+PRODUCT(SEMANAL!$B14,H$14)/1000 -> 0 | I23: =PRODUCT(SEMANAL!$D14,I$13)/1000+PRODUCT(SEMANAL!$B14,I$14)/1000 -> 0 | ... N23: =PRODUCT(SEMANAL!$D14,N$13)/1000+PRODUCT(SEMANAL!$B14,N$14)/1000 -> 0.5 | O23: =SUM('OC FRUT y VERD AZUL 2'!B23:N23) -> 17 | P23: 1590 | Q23: =O23*P23 -> 27030
A24: Tomate | B24: =PRODUCT(SEMANAL!$D15,B$13)/1000+PRODUCT(SEMANAL!$B15,B$14)/1000 -> 1.645 | C24: =PRODUCT(SEMANAL!$D15,C$13)/1000+PRODUCT(SEMANAL!$B15,C$14)/1000 -> 0 | D24: =PRODUCT(SEMANAL!$D15,D$13)/1000+PRODUCT(SEMANAL!$B15,D$14)/1000 -> 0.105 | E24: =PRODUCT(SEMANAL!$D15,E$13)/1000+PRODUCT(SEMANAL!$B15,E$14)/1000 -> 2.87 | F24: =PRODUCT(SEMANAL!$D15,F$13)/1000+PRODUCT(SEMANAL!$B15,F$14)/1000 -> 0 | G24: =PRODUCT(SEMANAL!$D15,G$13)/1000+PRODUCT(SEMANAL!$B15,G$14)/1000 -> 0.49 | H24: =PRODUCT(SEMANAL!$D15,H$13)/1000+PRODUCT(SEMANAL!$B15,H$14)/1000 -> 0 | I24: =PRODUCT(SEMANAL!$D15,I$13)/1000+PRODUCT(SEMANAL!$B15,I$14)/1000 -> 0 | ... N24: =PRODUCT(SEMANAL!$D15,N$13)/1000+PRODUCT(SEMANAL!$B15,N$14)/1000 -> 0.35 | O24: =SUM('OC FRUT y VERD AZUL 2'!B24:N24) -> 13 | P24: 1890 | Q24: =O24*P24 -> 24570
A25: Ajo | B25: =PRODUCT(SEMANAL!$D16,B$13)/1000+PRODUCT(SEMANAL!$B16,B$14)/1000 -> 0.0094 | C25: =PRODUCT(SEMANAL!$D16,C$13)/1000+PRODUCT(SEMANAL!$B16,C$14)/1000 -> 0 | D25: =PRODUCT(SEMANAL!$D16,D$13)/1000+PRODUCT(SEMANAL!$B16,D$14)/1000 -> 0.0006 | E25: =PRODUCT(SEMANAL!$D16,E$13)/1000+PRODUCT(SEMANAL!$B16,E$14)/1000 -> 0.0164 | F25: =PRODUCT(SEMANAL!$D16,F$13)/1000+PRODUCT(SEMANAL!$B16,F$14)/1000 -> 0 | G25: =PRODUCT(SEMANAL!$D16,G$13)/1000+PRODUCT(SEMANAL!$B16,G$14)/1000 -> 0.0028 | H25: =PRODUCT(SEMANAL!$D16,H$13)/1000+PRODUCT(SEMANAL!$B16,H$14)/1000 -> 0 | I25: =PRODUCT(SEMANAL!$D16,I$13)/1000+PRODUCT(SEMANAL!$B16,I$14)/1000 -> 0 | ... N25: =PRODUCT(SEMANAL!$D16,N$13)/1000+PRODUCT(SEMANAL!$B16,N$14)/1000 -> 0.002 | O25: =SUM('OC FRUT y VERD AZUL 2'!B25:N25) -> 6 | P25: 700 | Q25: =O25*P25 -> 4200
A26: Perejil | B26: =PRODUCT(SEMANAL!$D17,B$13)/1000+PRODUCT(SEMANAL!$B17,B$14)/1000 -> 0.0094 | C26: =PRODUCT(SEMANAL!$D17,C$13)/1000+PRODUCT(SEMANAL!$B17,C$14)/1000 -> 0 | D26: =PRODUCT(SEMANAL!$D17,D$13)/1000+PRODUCT(SEMANAL!$B17,D$14)/1000 -> 0.0006 | E26: =PRODUCT(SEMANAL!$D17,E$13)/1000+PRODUCT(SEMANAL!$B17,E$14)/1000 -> 0.0164 | F26: =PRODUCT(SEMANAL!$D17,F$13)/1000+PRODUCT(SEMANAL!$B17,F$14)/1000 -> 0 | G26: =PRODUCT(SEMANAL!$D17,G$13)/1000+PRODUCT(SEMANAL!$B17,G$14)/1000 -> 0.0028 | H26: =PRODUCT(SEMANAL!$D17,H$13)/1000+PRODUCT(SEMANAL!$B17,H$14)/1000 -> 0 | I26: =PRODUCT(SEMANAL!$D17,I$13)/1000+PRODUCT(SEMANAL!$B17,I$14)/1000 -> 0 | ... N26: =PRODUCT(SEMANAL!$D17,N$13)/1000+PRODUCT(SEMANAL!$B17,N$14)/1000 -> 0.002 | O26: =SUM('OC FRUT y VERD AZUL 2'!B26:N26) -> 6 | P26: 1990 | Q26: =O26*P26 -> 11940
A27: Huevo de gallina x doc | B27: =PRODUCT(SEMANAL!$D18,B$13)/12+PRODUCT(SEMANAL!$B18,B$14)/12 -> 5.875 | C27: =PRODUCT(SEMANAL!$D18,C$13)/12+PRODUCT(SEMANAL!$B18,C$14)/12 -> 0 | D27: =PRODUCT(SEMANAL!$D18,D$13)/12+PRODUCT(SEMANAL!$B18,D$14)/12 -> 0.375 | E27: =PRODUCT(SEMANAL!$D18,E$13)/12+PRODUCT(SEMANAL!$B18,E$14)/12 -> 10.25 | F27: =PRODUCT(SEMANAL!$D18,F$13)/12+PRODUCT(SEMANAL!$B18,F$14)/12 -> 0 | G27: =PRODUCT(SEMANAL!$D18,G$13)/12+PRODUCT(SEMANAL!$B18,G$14)/12 -> 1.75 | H27: =PRODUCT(SEMANAL!$D18,H$13)/12+PRODUCT(SEMANAL!$B18,H$14)/12 -> 0 | I27: =PRODUCT(SEMANAL!$D18,I$13)/12+PRODUCT(SEMANAL!$B18,I$14)/12 -> 0 | ... N27: =PRODUCT(SEMANAL!$D18,N$13)/12+PRODUCT(SEMANAL!$B18,N$14)/12 -> 1.25 | O27: =SUM('OC FRUT y VERD AZUL 2'!B27:N27) -> 46 | P27: 2100 | Q27: =O27*P27 -> 96600
P31: TOTAL | Q31: =Q15+Q16+Q17+Q18+Q19+Q20+Q21+Q22+Q23+Q24+Q25+Q26+Q27 -> 1331280
B37: EP 26 | C37: EP 27 | D37: EP 33 | E37: EP36 JIR2 | F37: EP 37 | G37: EP38 JIR15 | H37: EP39 JIR10 | I37: EP 41 | J37: EP 43 | K37: EP50 JIR 13 | L37: EP 53 | M37: EP 55 | N37: EP57 JIR 11
B38: 49 | C38: 230 | D38: 19 | E38: 38 | F38: 26 | G38: 5 | H38: 5 | I38: 8 | J38: 8 | K38: 7 | L38: 10 | M38: 17 | N38: 9
B39: 40 | C39: 115 | D39: 0 | E39: 0 | F39: 13 | G39: 1 | H39: 0 | I39: 0 | J39: 0 | K39: 0 | L39: 0 | M39: 0 | N39: 3
A40: MANZANA | B40: =PRODUCT(SEMANAL!$D6,B$38)/1000+PRODUCT(SEMANAL!$B6,B$39)/1000 -> 10.925 | C40: =PRODUCT(SEMANAL!$D6,C$38)/1000+PRODUCT(SEMANAL!$B6,C$39)/1000 -> 42.55 | D40: =PRODUCT(SEMANAL!$D6,D$38)/1000+PRODUCT(SEMANAL!$B6,D$39)/1000 -> 2.375 | E40: =PRODUCT(SEMANAL!$D6,E$38)/1000+PRODUCT(SEMANAL!$B6,E$39)/1000 -> 4.75 | F40: =PRODUCT(SEMANAL!$D6,F$38)/1000+PRODUCT(SEMANAL!$B6,F$39)/1000 -> 4.81 | G40: =PRODUCT(SEMANAL!$D6,G$38)/1000+PRODUCT(SEMANAL!$B6,G$39)/1000 -> 0.745 | H40: =PRODUCT(SEMANAL!$D6,H$38)/1000+PRODUCT(SEMANAL!$B6,H$39)/1000 -> 0.625 | I40: =PRODUCT(SEMANAL!$D6,I$38)/1000+PRODUCT(SEMANAL!$B6,I$39)/1000 -> 1 | ... N40: =PRODUCT(SEMANAL!$D6,N$38)/1000+PRODUCT(SEMANAL!$B6,N$39)/1000 -> 1.485 | O40: =SUM('OC FRUT y VERD AZUL 2'!B36:N36) -> 64 | P40: 2390 | Q40: =O40*P40 -> 152960
A41: BANANA | B41: =PRODUCT(SEMANAL!$D$7,B$38)/1000+PRODUCT(SEMANAL!$B$7,B$39)/1000 -> 4.8 | C41: =PRODUCT(SEMANAL!$D$7,C$38)/1000+PRODUCT(SEMANAL!$B$7,C$39)/1000 -> 13.8 | D41: =PRODUCT(SEMANAL!$D$7,D$38)/1000+PRODUCT(SEMANAL!$B$7,D$39)/1000 -> 0 | E41: =PRODUCT(SEMANAL!$D$7,E$38)/1000+PRODUCT(SEMANAL!$B$7,E$39)/1000 -> 0 | F41: =PRODUCT(SEMANAL!$D$7,F$38)/1000+PRODUCT(SEMANAL!$B$7,F$39)/1000 -> 1.56 | G41: =PRODUCT(SEMANAL!$D$7,G$38)/1000+PRODUCT(SEMANAL!$B$7,G$39)/1000 -> 0.12 | H41: =PRODUCT(SEMANAL!$D$7,H$38)/1000+PRODUCT(SEMANAL!$B$7,H$39)/1000 -> 0 | I41: =PRODUCT(SEMANAL!$D$7,I$38)/1000+PRODUCT(SEMANAL!$B$7,I$39)/1000 -> 0 | ... N41: =PRODUCT(SEMANAL!$D$7,N$38)/1000+PRODUCT(SEMANAL!$B$7,N$39)/1000 -> 0.36 | O41: =SUM('OC FRUT y VERD AZUL 2'!B37:N37) -> 22 | P41: 2550 | Q41: =O41*P41 -> 56100
A42: NARANJA O MANDARINA | B42: =PRODUCT(SEMANAL!$D8,B$38)/1000+PRODUCT(SEMANAL!$B8,B$39)/1000 -> 21.85 | C42: =PRODUCT(SEMANAL!$D8,C$38)/1000+PRODUCT(SEMANAL!$B8,C$39)/1000 -> 85.1 | D42: =PRODUCT(SEMANAL!$D8,D$38)/1000+PRODUCT(SEMANAL!$B8,D$39)/1000 -> 4.75 | E42: =PRODUCT(SEMANAL!$D8,E$38)/1000+PRODUCT(SEMANAL!$B8,E$39)/1000 -> 9.5 | F42: =PRODUCT(SEMANAL!$D8,F$38)/1000+PRODUCT(SEMANAL!$B8,F$39)/1000 -> 9.62 | G42: =PRODUCT(SEMANAL!$D8,G$38)/1000+PRODUCT(SEMANAL!$B8,G$39)/1000 -> 1.49 | H42: =PRODUCT(SEMANAL!$D8,H$38)/1000+PRODUCT(SEMANAL!$B8,H$39)/1000 -> 1.25 | I42: =PRODUCT(SEMANAL!$D8,I$38)/1000+PRODUCT(SEMANAL!$B8,I$39)/1000 -> 2 | ... N42: =PRODUCT(SEMANAL!$D8,N$38)/1000+PRODUCT(SEMANAL!$B8,N$39)/1000 -> 2.97 | O42: =SUM('OC FRUT y VERD AZUL 2'!B38:N38) -> 142 | P42: 1710 | Q42: =O42*P42 -> 242820
A43: PERA | B43: =PRODUCT(SEMANAL!$D9,B$38)/1000+PRODUCT(SEMANAL!$B9,B$39)/1000 -> 0 | C43: =PRODUCT(SEMANAL!$D9,C$38)/1000+PRODUCT(SEMANAL!$B9,C$39)/1000 -> 0 | D43: =PRODUCT(SEMANAL!$D9,D$38)/1000+PRODUCT(SEMANAL!$B9,D$39)/1000 -> 0 | E43: =PRODUCT(SEMANAL!$D9,E$38)/1000+PRODUCT(SEMANAL!$B9,E$39)/1000 -> 0 | F43: =PRODUCT(SEMANAL!$D9,F$38)/1000+PRODUCT(SEMANAL!$B9,F$39)/1000 -> 0 | G43: =PRODUCT(SEMANAL!$D9,G$38)/1000+PRODUCT(SEMANAL!$B9,G$39)/1000 -> 0 | H43: =PRODUCT(SEMANAL!$D9,H$38)/1000+PRODUCT(SEMANAL!$B9,H$39)/1000 -> 0 | I43: =PRODUCT(SEMANAL!$D9,I$38)/1000+PRODUCT(SEMANAL!$B9,I$39)/1000 -> 0 | ... N43: =PRODUCT(SEMANAL!$D9,N$38)/1000+PRODUCT(SEMANAL!$B9,N$39)/1000 -> 0 | O43: =SUM('OC FRUT y VERD AZUL 2'!B39:N39) -> 0 | P43: 2200 | Q43: =O43*P43 -> 0
A44: Zapallo ANCO | B44: =PRODUCT(SEMANAL!$D10,B$38)/1000+PRODUCT(SEMANAL!$B10,B$39)/1000 -> 5.6 | C44: =PRODUCT(SEMANAL!$D10,C$38)/1000+PRODUCT(SEMANAL!$B10,C$39)/1000 -> 16.1 | D44: =PRODUCT(SEMANAL!$D10,D$38)/1000+PRODUCT(SEMANAL!$B10,D$39)/1000 -> 0 | E44: =PRODUCT(SEMANAL!$D10,E$38)/1000+PRODUCT(SEMANAL!$B10,E$39)/1000 -> 0 | F44: =PRODUCT(SEMANAL!$D10,F$38)/1000+PRODUCT(SEMANAL!$B10,F$39)/1000 -> 1.82 | G44: =PRODUCT(SEMANAL!$D10,G$38)/1000+PRODUCT(SEMANAL!$B10,G$39)/1000 -> 0.14 | H44: =PRODUCT(SEMANAL!$D10,H$38)/1000+PRODUCT(SEMANAL!$B10,H$39)/1000 -> 0 | I44: =PRODUCT(SEMANAL!$D10,I$38)/1000+PRODUCT(SEMANAL!$B10,I$39)/1000 -> 0 | ... N44: =PRODUCT(SEMANAL!$D10,N$38)/1000+PRODUCT(SEMANAL!$B10,N$39)/1000 -> 0.42 | O44: =SUM('OC FRUT y VERD AZUL 2'!B40:N40) -> 26 | P44: 1350 | Q44: =O44*P44 -> 35100
A45: Zapallo verde | B45: =PRODUCT(SEMANAL!$D11,B$38)/1000+PRODUCT(SEMANAL!B$11,B$39)/1000 -> 2 | C45: =PRODUCT(SEMANAL!$D11,C$38)/1000+PRODUCT(SEMANAL!C$11,C$39)/1000 -> 0.115 | D45: =PRODUCT(SEMANAL!$D11,D$38)/1000+PRODUCT(SEMANAL!D$11,D$39)/1000 -> 0 | E45: =PRODUCT(SEMANAL!$D11,E$38)/1000+PRODUCT(SEMANAL!E$11,E$39)/1000 -> 0 | F45: =PRODUCT(SEMANAL!$D11,F$38)/1000+PRODUCT(SEMANAL!F$11,F$39)/1000 -> 0.65 | G45: =PRODUCT(SEMANAL!$D11,G$38)/1000+PRODUCT(SEMANAL!G$11,G$39)/1000 -> 0 | H45: =PRODUCT(SEMANAL!$D11,H$38)/1000+PRODUCT(SEMANAL!H$11,H$39)/1000 -> 0 | I45: =PRODUCT(SEMANAL!$D11,I$38)/1000+PRODUCT(SEMANAL!I$11,I$39)/1000 -> 0 | ... N45: =PRODUCT(SEMANAL!$D11,N$38)/1000+PRODUCT(SEMANAL!N$11,N$39)/1000 -> 0.003 | O45: =SUM('OC FRUT y VERD AZUL 2'!B41:N41) -> 2 | P45: 1950 | Q45: =O45*P45 -> 3900
A46: Papa | B46: =PRODUCT(SEMANAL!$D12,B$38)/1000+PRODUCT(SEMANAL!$B12,B$39)/1000 -> 8 | C46: =PRODUCT(SEMANAL!$D12,C$38)/1000+PRODUCT(SEMANAL!$B12,C$39)/1000 -> 23 | D46: =PRODUCT(SEMANAL!$D12,D$38)/1000+PRODUCT(SEMANAL!$B12,D$39)/1000 -> 0 | E46: =PRODUCT(SEMANAL!$D12,E$38)/1000+PRODUCT(SEMANAL!$B12,E$39)/1000 -> 0 | F46: =PRODUCT(SEMANAL!$D12,F$38)/1000+PRODUCT(SEMANAL!$B12,F$39)/1000 -> 2.6 | G46: =PRODUCT(SEMANAL!$D12,G$38)/1000+PRODUCT(SEMANAL!$B12,G$39)/1000 -> 0.2 | H46: =PRODUCT(SEMANAL!$D12,H$38)/1000+PRODUCT(SEMANAL!$B12,H$39)/1000 -> 0 | I46: =PRODUCT(SEMANAL!$D12,I$38)/1000+PRODUCT(SEMANAL!$B12,I$39)/1000 -> 0 | ... N46: =PRODUCT(SEMANAL!$D12,N$38)/1000+PRODUCT(SEMANAL!$B12,N$39)/1000 -> 0.6 | O46: =SUM('OC FRUT y VERD AZUL 2'!B42:N42) -> 35 | P46: 1090 | Q46: =O46*P46 -> 38150
A47: Cebolla | B47: =PRODUCT(SEMANAL!$D13,B$38)/1000+PRODUCT(SEMANAL!$B13,B$39)/1000 -> 3 | C47: =PRODUCT(SEMANAL!$D13,C$38)/1000+PRODUCT(SEMANAL!$B13,C$39)/1000 -> 8.625 | D47: =PRODUCT(SEMANAL!$D13,D$38)/1000+PRODUCT(SEMANAL!$B13,D$39)/1000 -> 0 | E47: =PRODUCT(SEMANAL!$D13,E$38)/1000+PRODUCT(SEMANAL!$B13,E$39)/1000 -> 0 | F47: =PRODUCT(SEMANAL!$D13,F$38)/1000+PRODUCT(SEMANAL!$B13,F$39)/1000 -> 0.975 | G47: =PRODUCT(SEMANAL!$D13,G$38)/1000+PRODUCT(SEMANAL!$B13,G$39)/1000 -> 0.075 | H47: =PRODUCT(SEMANAL!$D13,H$38)/1000+PRODUCT(SEMANAL!$B13,H$39)/1000 -> 0 | I47: =PRODUCT(SEMANAL!$D13,I$38)/1000+PRODUCT(SEMANAL!$B13,I$39)/1000 -> 0 | ... N47: =PRODUCT(SEMANAL!$D13,N$38)/1000+PRODUCT(SEMANAL!$B13,N$39)/1000 -> 0.225 | O47: =SUM('OC FRUT y VERD AZUL 2'!B43:N43) -> 10 | P47: 1090 | Q47: =O47*P47 -> 10900
A48: Zanahoria | B48: =PRODUCT(SEMANAL!$D14,B$38)/1000+PRODUCT(SEMANAL!$B14,B$39)/1000 -> 2 | C48: =PRODUCT(SEMANAL!$D14,C$38)/1000+PRODUCT(SEMANAL!$B14,C$39)/1000 -> 5.75 | D48: =PRODUCT(SEMANAL!$D14,D$38)/1000+PRODUCT(SEMANAL!$B14,D$39)/1000 -> 0 | E48: =PRODUCT(SEMANAL!$D14,E$38)/1000+PRODUCT(SEMANAL!$B14,E$39)/1000 -> 0 | F48: =PRODUCT(SEMANAL!$D14,F$38)/1000+PRODUCT(SEMANAL!$B14,F$39)/1000 -> 0.65 | G48: =PRODUCT(SEMANAL!$D14,G$38)/1000+PRODUCT(SEMANAL!$B14,G$39)/1000 -> 0.05 | H48: =PRODUCT(SEMANAL!$D14,H$38)/1000+PRODUCT(SEMANAL!$B14,H$39)/1000 -> 0 | I48: =PRODUCT(SEMANAL!$D14,I$38)/1000+PRODUCT(SEMANAL!$B14,I$39)/1000 -> 0 | ... N48: =PRODUCT(SEMANAL!$D14,N$38)/1000+PRODUCT(SEMANAL!$B14,N$39)/1000 -> 0.15 | O48: =SUM('OC FRUT y VERD AZUL 2'!B44:N44) -> 7 | P48: 1590 | Q48: =O48*P48 -> 11130
A49: Tomate | B49: =PRODUCT(SEMANAL!$D15,B$38)/1000+PRODUCT(SEMANAL!$B15,B$39)/1000 -> 1.4 | C49: =PRODUCT(SEMANAL!$D15,C$38)/1000+PRODUCT(SEMANAL!$B15,C$39)/1000 -> 4.025 | D49: =PRODUCT(SEMANAL!$D15,D$38)/1000+PRODUCT(SEMANAL!$B15,D$39)/1000 -> 0 | E49: =PRODUCT(SEMANAL!$D15,E$38)/1000+PRODUCT(SEMANAL!$B15,E$39)/1000 -> 0 | F49: =PRODUCT(SEMANAL!$D15,F$38)/1000+PRODUCT(SEMANAL!$B15,F$39)/1000 -> 0.455 | G49: =PRODUCT(SEMANAL!$D15,G$38)/1000+PRODUCT(SEMANAL!$B15,G$39)/1000 -> 0.035 | H49: =PRODUCT(SEMANAL!$D15,H$38)/1000+PRODUCT(SEMANAL!$B15,H$39)/1000 -> 0 | I49: =PRODUCT(SEMANAL!$D15,I$38)/1000+PRODUCT(SEMANAL!$B15,I$39)/1000 -> 0 | ... N49: =PRODUCT(SEMANAL!$D15,N$38)/1000+PRODUCT(SEMANAL!$B15,N$39)/1000 -> 0.105 | O49: =SUM('OC FRUT y VERD AZUL 2'!B45:N45) -> 8 | P49: 1890 | Q49: =O49*P49 -> 15120
A50: Ajo | B50: =PRODUCT(SEMANAL!$D16,B$38)/1000+PRODUCT(SEMANAL!$B16,B$39)/1000 -> 0.008 | C50: =PRODUCT(SEMANAL!$D16,C$38)/1000+PRODUCT(SEMANAL!$B16,C$39)/1000 -> 0.023 | D50: =PRODUCT(SEMANAL!$D16,D$38)/1000+PRODUCT(SEMANAL!$B16,D$39)/1000 -> 0 | E50: =PRODUCT(SEMANAL!$D16,E$38)/1000+PRODUCT(SEMANAL!$B16,E$39)/1000 -> 0 | F50: =PRODUCT(SEMANAL!$D16,F$38)/1000+PRODUCT(SEMANAL!$B16,F$39)/1000 -> 0.0026 | G50: =PRODUCT(SEMANAL!$D16,G$38)/1000+PRODUCT(SEMANAL!$B16,G$39)/1000 -> 0.0002 | H50: =PRODUCT(SEMANAL!$D16,H$38)/1000+PRODUCT(SEMANAL!$B16,H$39)/1000 -> 0 | I50: =PRODUCT(SEMANAL!$D16,I$38)/1000+PRODUCT(SEMANAL!$B16,I$39)/1000 -> 0 | ... N50: =PRODUCT(SEMANAL!$D16,N$38)/1000+PRODUCT(SEMANAL!$B16,N$39)/1000 -> 0.0006 | O50: =SUM('OC FRUT y VERD AZUL 2'!B46:N46) -> 3 | P50: 700 | Q50: =O50*P50 -> 2100
A51: Perejil | B51: =PRODUCT(SEMANAL!$D17,B$38)/1000+PRODUCT(SEMANAL!$B17,B$39)/1000 -> 0.008 | C51: =PRODUCT(SEMANAL!$D17,C$38)/1000+PRODUCT(SEMANAL!$B17,C$39)/1000 -> 0.023 | D51: =PRODUCT(SEMANAL!$D17,D$38)/1000+PRODUCT(SEMANAL!$B17,D$39)/1000 -> 0 | E51: =PRODUCT(SEMANAL!$D17,E$38)/1000+PRODUCT(SEMANAL!$B17,E$39)/1000 -> 0 | F51: =PRODUCT(SEMANAL!$D17,F$38)/1000+PRODUCT(SEMANAL!$B17,F$39)/1000 -> 0.0026 | G51: =PRODUCT(SEMANAL!$D17,G$38)/1000+PRODUCT(SEMANAL!$B17,G$39)/1000 -> 0.0002 | H51: =PRODUCT(SEMANAL!$D17,H$38)/1000+PRODUCT(SEMANAL!$B17,H$39)/1000 -> 0 | I51: =PRODUCT(SEMANAL!$D17,I$38)/1000+PRODUCT(SEMANAL!$B17,I$39)/1000 -> 0 | ... N51: =PRODUCT(SEMANAL!$D17,N$38)/1000+PRODUCT(SEMANAL!$B17,N$39)/1000 -> 0.0006 | O51: =SUM('OC FRUT y VERD AZUL 2'!B47:N47) -> 2 | P51: 1990 | Q51: =O51*P51 -> 3980
A52: Huevo de gallina x doc | B52: =PRODUCT(SEMANAL!$D18,B$38)/12+PRODUCT(SEMANAL!$B18,B$39)/12 -> 5 | C52: =PRODUCT(SEMANAL!$D18,C$38)/12+PRODUCT(SEMANAL!$B18,C$39)/12 -> 14.375 | D52: =PRODUCT(SEMANAL!$D18,D$38)/12+PRODUCT(SEMANAL!$B18,D$39)/12 -> 0 | E52: =PRODUCT(SEMANAL!$D18,E$38)/12+PRODUCT(SEMANAL!$B18,E$39)/12 -> 0 | F52: =PRODUCT(SEMANAL!$D18,F$38)/12+PRODUCT(SEMANAL!$B18,F$39)/12 -> 1.625 | G52: =PRODUCT(SEMANAL!$D18,G$38)/12+PRODUCT(SEMANAL!$B18,G$39)/12 -> 0.125 | H52: =PRODUCT(SEMANAL!$D18,H$38)/12+PRODUCT(SEMANAL!$B18,H$39)/12 -> 0 | I52: =PRODUCT(SEMANAL!$D18,I$38)/12+PRODUCT(SEMANAL!$B18,I$39)/12 -> 0 | ... N52: =PRODUCT(SEMANAL!$D18,N$38)/12+PRODUCT(SEMANAL!$B18,N$39)/12 -> 0.375 | O52: =SUM('OC FRUT y VERD AZUL 2'!B48:N48) -> 17 | P52: 2100 | Q52: =O52*P52 -> 35700
P53: TOTAL | Q53: =Q40+Q41+Q42+Q43+Q44+Q45+Q46+Q47+Q48+Q49+Q50+Q51+Q52 -> 607960
B59: EP 62 | C59: EP 64 | D59: EP 65 | E59: EP 66 | F59: Ins. San | G59: EES 7 | H59: EES 8 | I59: EES 9 | J59: EES 9 | K59: EES 10 | L59: EES 11 | M59: EES 11 | N59: EES 12
...

Sheet OC FRUT y VERD AZUL 2
A6: AZUL PERIODO REGULAR 2026
A7: ORDEN DE COMPRA | F7: 14
A8: FECHA: | F8: 8 al 12 de junio
A10: FRUTAS Y VERDURAS:
A11: PROVEEDOR: FERNANDEZ ( LA PUNTUAL)
B12: EP 1 | C12: EP 7 | D12: EP 9 | E12: EP 13 | F12: EP 14 | G12: EP 16 | H12: EP 17 | I12: EP 18 | J12: EP 19 | K12: EP 21 | L12: EP 22 | M12: EP24 JIR7 | N12: EP25 JIR 4
B13: 94 | C13: 101 | D13: 6 | E13: 164 | F13: 90 | G13: 28 | H13: 27 | I13: 71 | J13: 148 | K13: 86 | L13: 92 | M13: 13 | N13: 22
B14: 47 | C14: 0 | D14: 3 | E14: 82 | F14: 0 | G14: 14 | H14: 0 | I14: 0 | J14: 87 | K14: 43 | L14: 56 | M14: 0 | N14: 10
A15: MANZANA | B15: 0 | C15: =ROUNDUP(' AZUL 2'!C15,0) -> 13 | D15: =ROUNDUP(' AZUL 2'!D15,0) -> 2 | E15: =ROUNDUP(' AZUL 2'!E15,0) -> 31 | F15: =ROUNDUP(' AZUL 2'!F15,0) -> 12 | G15: =ROUNDUP(' AZUL 2'!G15,0) -> 6 | H15: =ROUNDUP(' AZUL 2'!H15,0) -> 4 | I15: =ROUNDUP(' AZUL 2'!I15,0) -> 9 | J15: =ROUNDUP(' AZUL 2'!J15,0) -> 29 | ... N15: =ROUNDUP(' AZUL 2'!N15,0) -> 4
A16: BANANA | B16: =ROUNDUP(' AZUL 2'!B16,0) -> 6 | C16: =ROUNDUP(' AZUL 2'!C16,0) -> 0 | D16: =ROUNDUP(' AZUL 2'!D16,0) -> 1 | E16: =ROUNDUP(' AZUL 2'!E16,0) -> 10 | F16: =ROUNDUP(' AZUL 2'!F16,0) -> 0 | G16: =ROUNDUP(' AZUL 2'!G16,0) -> 2 | H16: =ROUNDUP(' AZUL 2'!H16,0) -> 0 | I16: =ROUNDUP(' AZUL 2'!I16,0) -> 0 | ... N16: =ROUNDUP(' AZUL 2'!N16,0) -> 2
A17: NARANJA O MANDARINA | B17: =ROUNDUP(' AZUL 2'!B17,0) -> 35 | C17: =ROUNDUP(' AZUL 2'!C17,0) -> 26 | D17: =ROUNDUP(' AZUL 2'!D17,0) -> 3 | E17: =ROUNDUP(' AZUL 2'!E17,0) -> 62 | F17: =ROUNDUP(' AZUL 2'!F17,0) -> 23 | G17: =ROUNDUP(' AZUL 2'!G17,0) -> 11 | H17: =ROUNDUP(' AZUL 2'!H17,0) -> 7 | I17: =ROUNDUP(' AZUL 2'!I17,0) -> 18 | ... N17: =ROUNDUP(' AZUL 2'!N17,0) -> 6
A18: PERA | B18: =ROUNDUP(' AZUL 2'!B18,0) -> 0 | C18: =ROUNDUP(' AZUL 2'!C18,0) -> 0 | D18: =ROUNDUP(' AZUL 2'!D18,0) -> 0 | E18: =ROUNDUP(' AZUL 2'!E18,0) -> 0 | F18: =ROUNDUP(' AZUL 2'!F18,0) -> 0 | G18: =ROUNDUP(' AZUL 2'!G18,0) -> 0 | H18: =ROUNDUP(' AZUL 2'!H18,0) -> 0 | I18: =ROUNDUP(' AZUL 2'!I18,0) -> 0 | J18: 0 | K18: =ROUNDUP(' AZUL 2'!K18,0) -> 1 | L18: =ROUNDUP(' AZUL 2'!L18,0) -> 1 | M18: =ROUNDUP(' AZUL 2'!M18,0) -> 0 | N18: 0
A19: Zapallo ANCO | B19: =ROUNDUP(' AZUL 2'!B19,0) -> 7 | C19: =ROUNDUP(' AZUL 2'!C19,0) -> 0 | D19: 0 | E19: =ROUNDUP(' AZUL 2'!E19,0) -> 12 | F19: =ROUNDUP(' AZUL 2'!F19,0) -> 0 | G19: =ROUNDUP(' AZUL 2'!G19,0) -> 2 | H19: =ROUNDUP(' AZUL 2'!H19,0) -> 0 | I19: =ROUNDUP(' AZUL 2'!I19,0) -> 0 | J19: =ROUNDUP(' AZUL 2'!J19,0) -> 13 | K19: =ROUNDUP(' AZUL 2'!K19,0) -> 7 | L19: =ROUNDUP(' AZUL 2'!L19,0) -> 8 | M19: =ROUNDUP(' AZUL 2'!M19,0) -> 0 | N19: 0
A20: Zapallo verde | B20: =ROUNDUP(' AZUL 2'!B20,0) -> 3 | C20: =ROUNDUP(' AZUL 2'!C20,0) -> 0 | D20: =ROUNDUP(' AZUL 2'!D20,0) -> 1 | E20: =ROUNDUP(' AZUL 2'!E20,0) -> 5 | F20: =ROUNDUP(' AZUL 2'!F20,0) -> 0 | G20: =ROUNDUP(' AZUL 2'!G20,0) -> 1 | H20: =ROUNDUP(' AZUL 2'!H20,0) -> 0 | I20: =ROUNDUP(' AZUL 2'!I20,0) -> 0 | ... M20: =ROUNDUP(' AZUL 2'!M20,0) -> 0 | N20: 0
A21: Papa | B21: =ROUNDUP(' AZUL 2'!B21,0) -> 10 | C21: =ROUNDUP(' AZUL 2'!C21,0) -> 0 | D21: =ROUNDUP(' AZUL 2'!D21,0) -> 1 | E21: =ROUNDUP(' AZUL 2'!E21,0) -> 17 | F21: =ROUNDUP(' AZUL 2'!F21,0) -> 0 | G21: =ROUNDUP(' AZUL 2'!G21,0) -> 3 | H21: =ROUNDUP(' AZUL 2'!H21,0) -> 0 | I21: =ROUNDUP(' AZUL 2'!I21,0) -> 0 | ... N21: =ROUNDUP(' AZUL 2'!N21,0) -> 2
A22: Cebolla | B22: =ROUNDUP(' AZUL 2'!B22,0) -> 4 | C22: =ROUNDUP(' AZUL 2'!C22,0) -> 0 | D22: =ROUNDUP(' AZUL 2'!D22,0) -> 1 | E22: =ROUNDUP(' AZUL 2'!E22,0) -> 7 | F22: =ROUNDUP(' AZUL 2'!F22,0) -> 0 | G22: =ROUNDUP(' AZUL 2'!G22,0) -> 2 | H22: =ROUNDUP(' AZUL 2'!H22,0) -> 0 | I22: =ROUNDUP(' AZUL 2'!I22,0) -> 0 | ... N22: =ROUNDUP(' AZUL 2'!N22,0) -> 1
A23: Zanahoria | B23: 0 | C23: =ROUNDUP(' AZUL 2'!C23,0) -> 0 | D23: 0 | E23: =ROUNDUP(' AZUL 2'!E23,0) -> 5 | F23: =ROUNDUP(' AZUL 2'!F23,0) -> 0 | G23: =ROUNDUP(' AZUL 2'!G23,0) -> 1 | H23: =ROUNDUP(' AZUL 2'!H23,0) -> 0 | I23: =ROUNDUP(' AZUL 2'!I23,0) -> 0 | J23: =ROUNDUP(' AZUL 2'!J23,0) -> 5 | K23: =ROUNDUP(' AZUL 2'!K23,0) -> 3 | L23: =ROUNDUP(' AZUL 2'!L23,0) -> 3 | M23: =ROUNDUP(' AZUL 2'!M23,0) -> 0 | N23: 0
A24: Tomate | B24: 0 | C24: =ROUNDUP(' AZUL 2'!C24,0) -> 0 | D24: 0 | E24: =ROUNDUP(' AZUL 2'!E24,0) -> 3 | F24: =ROUNDUP(' AZUL 2'!F24,0) -> 0 | G24: =ROUNDUP(' AZUL 2'!G24,0) -> 1 | H24: =ROUNDUP(' AZUL 2'!H24,0) -> 0 | I24: =ROUNDUP(' AZUL 2'!I24,0) -> 0 | J24: =ROUNDUP(' AZUL 2'!J24,0) -> 4 | K24: =ROUNDUP(' AZUL 2'!K24,0) -> 2 | L24: =ROUNDUP(' AZUL 2'!L24,0) -> 2 | ... N24: =ROUNDUP(' AZUL 2'!N24,0) -> 1
A25: Ajo | B25: =ROUNDUP(' AZUL 2'!B25,0) -> 1 | C25: =ROUNDUP(' AZUL 2'!C25,0) -> 0 | D25: 0 | E25: =ROUNDUP(' AZUL 2'!E25,0) -> 1 | F25: =ROUNDUP(' AZUL 2'!F25,0) -> 0 | G25: =ROUNDUP(' AZUL 2'!G25,0) -> 1 | H25: =ROUNDUP(' AZUL 2'!H25,0) -> 0 | I25: =ROUNDUP(' AZUL 2'!I25,0) -> 0 | J25: =ROUNDUP(' AZUL 2'!J25,0) -> 1 | K25: =ROUNDUP(' AZUL 2'!K25,0) -> 1 | L25: =ROUNDUP(' AZUL 2'!L25,0) -> 1 | M25: =ROUNDUP(' AZUL 2'!M25,0) -> 0 | N25: 0
A26: Perejil | B26: =ROUNDUP(' AZUL 2'!B26,0) -> 1 | C26: =ROUNDUP(' AZUL 2'!C26,0) -> 0 | D26: 0 | E26: =ROUNDUP(' AZUL 2'!E26,0) -> 1 | F26: =ROUNDUP(' AZUL 2'!F26,0) -> 0 | G26: =ROUNDUP(' AZUL 2'!G26,0) -> 1 | H26: =ROUNDUP(' AZUL 2'!H26,0) -> 0 | I26: =ROUNDUP(' AZUL 2'!I26,0) -> 0 | J26: =ROUNDUP(' AZUL 2'!J26,0) -> 1 | K26: =ROUNDUP(' AZUL 2'!K26,0) -> 1 | L26: =ROUNDUP(' AZUL 2'!L26,0) -> 1 | M26: =ROUNDUP(' AZUL 2'!M26,0) -> 0 | N26: 0
A27: Huevo de gallina x doc | B27: =ROUNDUP(' AZUL 2'!B$27,0) -> 6 | C27: =ROUNDUP(' AZUL 2'!C$27,0) -> 0 | D27: =ROUNDUP(' AZUL 2'!D$27,0) -> 1 | E27: =ROUNDUP(' AZUL 2'!E$27,0) -> 11 | F27: =ROUNDUP(' AZUL 2'!F$27,0) -> 0 | G27: =ROUNDUP(' AZUL 2'!G$27,0) -> 2 | H27: =ROUNDUP(' AZUL 2'!H$27,0) -> 0 | I27: =ROUNDUP(' AZUL 2'!I$27,0) -> 0 | ... N27: =ROUNDUP(' AZUL 2'!N$27,0) -> 2
B33: EP 26 | C33: EP 27 | D33: EP 33 | E33: EP36 JIR2 | F33: EP 37 | G33: EP38 JIR15 | H33: EP39 JIR10 | I33: EP 41 | J33: EP 43 | K33: EP50 JIR 13 | L33: EP 53 | M33: EP 55 | N33: EP57 JIR 11
B34: 49 | C34: 230 | D34: 19 | E34: 38 | F34: 26 | G34: 5 | H34: 5 | I34: 8 | J34: 8 | K34: 7 | L34: 10 | M34: 17 | N34: 9
B35: 40 | C35: 115 | D35: 0 | E35: 0 | F35: 13 | G35: 1 | H35: 0 | I35: 0 | J35: 0 | K35: 0 | L35: 0 | M35: 0 | N35: 3
A36: MANZANA | B36: 0 | C36: =ROUNDUP(' AZUL 2'!C40,0) -> 43 | D36: 2 | E36: =ROUNDUP(' AZUL 2'!E40,0) -> 5 | F36: =ROUNDUP(' AZUL 2'!F40,0) -> 5 | G36: 0 | H36: 0 | I36: =ROUNDUP(' AZUL 2'!I40,0) -> 1 | J36: =ROUNDUP(' AZUL 2'!J40,0) -> 1 | K36: 0 | L36: =ROUNDUP(' AZUL 2'!L40,0) -> 2 | M36: =ROUNDUP(' AZUL 2'!M40,0) -> 3 | N36: =ROUNDUP(' AZUL 2'!N40,0) -> 2
A37: BANANA | B37: =ROUNDUP(' AZUL 2'!B41,0) -> 5 | C37: =ROUNDUP(' AZUL 2'!C41,0) -> 14 | D37: =ROUNDUP(' AZUL 2'!D41,0) -> 0 | E37: =ROUNDUP(' AZUL 2'!E41,0) -> 0 | F37: =ROUNDUP(' AZUL 2'!F41,0) -> 2 | G37: 0 | H37: 0 | I37: =ROUNDUP(' AZUL 2'!I41,0) -> 0 | J37: =ROUNDUP(' AZUL 2'!J41,0) -> 0 | K37: 0 | L37: =ROUNDUP(' AZUL 2'!L41,0) -> 0 | M37: =ROUNDUP(' AZUL 2'!M41,0) -> 0 | N37: =ROUNDUP(' AZUL 2'!N41,0) -> 1
A38: NARANJA O MANDARINA | B38: =ROUNDUP(' AZUL 2'!B42,0) -> 22 | C38: =ROUNDUP(' AZUL 2'!C42,0) -> 86 | D38: 2 | E38: =ROUNDUP(' AZUL 2'!E42,0) -> 10 | F38: =ROUNDUP(' AZUL 2'!F42,0) -> 10 | G38: 0 | H38: 0 | I38: =ROUNDUP(' AZUL 2'!I42,0) -> 2 | J38: =ROUNDUP(' AZUL 2'!J42,0) -> 2 | K38: 0 | L38: =ROUNDUP(' AZUL 2'!L42,0) -> 3 | M38: =ROUNDUP(' AZUL 2'!M42,0) -> 5 | N38: 0
A39: PERA | B39: =ROUNDUP(' AZUL 2'!B43,0) -> 0 | C39: =ROUNDUP(' AZUL 2'!C43,0) -> 0 | D39: =ROUNDUP(' AZUL 2'!D43,0) -> 0 | E39: =ROUNDUP(' AZUL 2'!E43,0) -> 0 | F39: =ROUNDUP(' AZUL 2'!F43,0) -> 0 | G39: 0 | H39: 0 | I39: =ROUNDUP(' AZUL 2'!I43,0) -> 0 | J39: =ROUNDUP(' AZUL 2'!J43,0) -> 0 | K39: 0 | L39: =ROUNDUP(' AZUL 2'!L43,0) -> 0 | M39: =ROUNDUP(' AZUL 2'!M43,0) -> 0 | N39: =ROUNDUP(' AZUL 2'!N43,0) -> 0
A40: Zapallo ANCO | B40: =ROUNDUP(' AZUL 2'!B44,0) -> 6 | C40: =ROUNDUP(' AZUL 2'!C44,0) -> 17 | D40: =ROUNDUP(' AZUL 2'!D44,0) -> 0 | E40: =ROUNDUP(' AZUL 2'!E44,0) -> 0 | F40: =ROUNDUP(' AZUL 2'!F44,0) -> 2 | G40: 0 | H40: =ROUNDUP(' AZUL 2'!H44,0) -> 0 | I40: =ROUNDUP(' AZUL 2'!I44,0) -> 0 | J40: =ROUNDUP(' AZUL 2'!J44,0) -> 0 | K40: =ROUNDUP(' AZUL 2'!K44,0) -> 0 | L40: =ROUNDUP(' AZUL 2'!L44,0) -> 0 | M40: =ROUNDUP(' AZUL 2'!M44,0) -> 0 | N40: =ROUNDUP(' AZUL 2'!N44,0) -> 1
A41: Zapallo verde | B41: 0 | C41: =ROUNDUP(' AZUL 2'!C45,0) -> 1 | D41: =ROUNDUP(' AZUL 2'!D45,0) -> 0 | E41: =ROUNDUP(' AZUL 2'!E45,0) -> 0 | F41: =ROUNDUP(' AZUL 2'!F45,0) -> 1 | G41: 0 | H41: =ROUNDUP(' AZUL 2'!H45,0) -> 0 | I41: =ROUNDUP(' AZUL 2'!I45,0) -> 0 | J41: =ROUNDUP(' AZUL 2'!J45,0) -> 0 | K41: =ROUNDUP(' AZUL 2'!K45,0) -> 0 | L41: =ROUNDUP(' AZUL 2'!L45,0) -> 0 | M41: =ROUNDUP(' AZUL 2'!M45,0) -> 0 | N41: 0
A42: Papa | B42: =ROUNDUP(' AZUL 2'!B46,0) -> 8 | C42: =ROUNDUP(' AZUL 2'!C46,0) -> 23 | D42: =ROUNDUP(' AZUL 2'!D46,0) -> 0 | E42: =ROUNDUP(' AZUL 2'!E46,0) -> 0 | F42: =ROUNDUP(' AZUL 2'!F46,0) -> 3 | G42: 0 | H42: =ROUNDUP(' AZUL 2'!H46,0) -> 0 | I42: =ROUNDUP(' AZUL 2'!I46,0) -> 0 | J42: =ROUNDUP(' AZUL 2'!J46,0) -> 0 | K42: =ROUNDUP(' AZUL 2'!K46,0) -> 0 | L42: =ROUNDUP(' AZUL 2'!L46,0) -> 0 | M42: =ROUNDUP(' AZUL 2'!M46,0) -> 0 | N42: =ROUNDUP(' AZUL 2'!N46,0) -> 1
A43: Cebolla | B43: 0 | C43: =ROUNDUP(' AZUL 2'!C47,0) -> 9 | D43: =ROUNDUP(' AZUL 2'!D47,0) -> 0 | E43: =ROUNDUP(' AZUL 2'!E47,0) -> 0 | F43: =ROUNDUP(' AZUL 2'!F47,0) -> 1 | G43: 0 | H43: =ROUNDUP(' AZUL 2'!H47,0) -> 0 | I43: =ROUNDUP(' AZUL 2'!I47,0) -> 0 | J43: =ROUNDUP(' AZUL 2'!J47,0) -> 0 | K43: =ROUNDUP(' AZUL 2'!K47,0) -> 0 | L43: =ROUNDUP(' AZUL 2'!L47,0) -> 0 | M43: =ROUNDUP(' AZUL 2'!M47,0) -> 0 | N43: 0
A44: Zanahoria | B44: 0 | C44: =ROUNDUP(' AZUL 2'!C48,0) -> 6 | D44: =ROUNDUP(' AZUL 2'!D48,0) -> 0 | E44: =ROUNDUP(' AZUL 2'!E48,0) -> 0 | F44: =ROUNDUP(' AZUL 2'!F48,0) -> 1 | G44: 0 | H44: =ROUNDUP(' AZUL 2'!H48,0) -> 0 | I44: =ROUNDUP(' AZUL 2'!I48,0) -> 0 | J44: =ROUNDUP(' AZUL 2'!J48,0) -> 0 | K44: =ROUNDUP(' AZUL 2'!K48,0) -> 0 | L44: =ROUNDUP(' AZUL 2'!L48,0) -> 0 | M44: =ROUNDUP(' AZUL 2'!M48,0) -> 0 | N44: 0
A45: Tomate | B45: =ROUNDUP(' AZUL 2'!B49,0) -> 2 | C45: =ROUNDUP(' AZUL 2'!C49,0) -> 5 | D45: =ROUNDUP(' AZUL 2'!D49,0) -> 0 | E45: =ROUNDUP(' AZUL 2'!E49,0) -> 0 | F45: =ROUNDUP(' AZUL 2'!F49,0) -> 1 | G45: 0 | H45: =ROUNDUP(' AZUL 2'!H49,0) -> 0 | I45: =ROUNDUP(' AZUL 2'!I49,0) -> 0 | J45: =ROUNDUP(' AZUL 2'!J49,0) -> 0 | K45: =ROUNDUP(' AZUL 2'!K49,0) -> 0 | L45: =ROUNDUP(' AZUL 2'!L49,0) -> 0 | M45: =ROUNDUP(' AZUL 2'!M49,0) -> 0 | N45: 0
A46: Ajo | B46: =ROUNDUP(' AZUL 2'!B50,0) -> 1 | C46: =ROUNDUP(' AZUL 2'!C50,0) -> 1 | D46: =ROUNDUP(' AZUL 2'!D50,0) -> 0 | E46: =ROUNDUP(' AZUL 2'!E50,0) -> 0 | F46: =ROUNDUP(' AZUL 2'!F50,0) -> 1 | G46: 0 | H46: =ROUNDUP(' AZUL 2'!H50,0) -> 0 | I46: =ROUNDUP(' AZUL 2'!I50,0) -> 0 | J46: =ROUNDUP(' AZUL 2'!J50,0) -> 0 | K46: =ROUNDUP(' AZUL 2'!K50,0) -> 0 | L46: =ROUNDUP(' AZUL 2'!L50,0) -> 0 | M46: =ROUNDUP(' AZUL 2'!M50,0) -> 0 | N46: 0
A47: Perejil | B47: 0 | C47: =ROUNDUP(' AZUL 2'!C51,0) -> 1 | D47: =ROUNDUP(' AZUL 2'!D51,0) -> 0 | E47: =ROUNDUP(' AZUL 2'!E51,0) -> 0 | F47: =ROUNDUP(' AZUL 2'!F51,0) -> 1 | G47: 0 | H47: =ROUNDUP(' AZUL 2'!H51,0) -> 0 | I47: =ROUNDUP(' AZUL 2'!I51,0) -> 0 | J47: =ROUNDUP(' AZUL 2'!J51,0) -> 0 | K47: =ROUNDUP(' AZUL 2'!K51,0) -> 0 | L47: =ROUNDUP(' AZUL 2'!L51,0) -> 0 | M47: =ROUNDUP(' AZUL 2'!M51,0) -> 0 | N47: 0
A48: Huevo de gallina x doc | B48: 0 | C48: =ROUNDUP(' AZUL 2'!C$52,0) -> 15 | D48: =ROUNDUP(' AZUL 2'!D$52,0) -> 0 | E48: =ROUNDUP(' AZUL 2'!E$52,0) -> 0 | F48: =ROUNDUP(' AZUL 2'!F$52,0) -> 2 | G48: 0 | H48: =ROUNDUP(' AZUL 2'!H$52,0) -> 0 | I48: =ROUNDUP(' AZUL 2'!I$52,0) -> 0 | J48: =ROUNDUP(' AZUL 2'!J$52,0) -> 0 | K48: =ROUNDUP(' AZUL 2'!K$52,0) -> 0 | L48: =ROUNDUP(' AZUL 2'!L$52,0) -> 0 | M48: =ROUNDUP(' AZUL 2'!M$52,0) -> 0 | N48: 0
B55: EP 62 | C55: EP 64 | D55: EP 65 | E55: EP 66 | F55: Ins. San | G55: EES 7 | H55: EES 8 | I55: EES 9 | J55: EES 9 | K55: EES 10 | L55: EES 11 | M55: EES 11 | N55: EES 12
F56: PRIM | I56: EP 7 | J56: EP 21 | L56: EP 18 | M56: EP 14 | N56: EP 27
B57: 167 | C57: 148 | D57: 7 | E57: 178 | F57: 108 | G57: 35 | H57: 149 | I57: 99 | J57: 33 | K57: 150 | L57: 123 | M57: 78 | N57: 170
...

Sheet OC SECOS y LAC AZUL 2
A6: AZUL PERIODO REGULAR 2026
A7: ORDEN DE COMPRA
A8: FECHA:
A10: LACTEOS Y SECOS -
A11: AZUL- PROVEEDOR TUX SA - LACTEOS Y SECOS- PEDIDO SEMANAL-
B13: EP 1 | C13: EP 7 | D13: EP 9 | E13: EP 13 | F13: EP 14 | G13: EP 16 | H13: EP 17 | I13: EP 18 | J13: EP 19 | K13: EP 21 | L13: EP 22 | M13: EP24 JIR7 | N13: EP25 JIR 4
B14: 94 | C14: 101 | D14: 6 | E14: 164 | F14: 90 | G14: 28 | H14: 27 | I14: 71 | J14: 148 | K14: 86 | L14: 92 | M14: 13 | N14: 22
B15: 47 | C15: 0 | D15: 3 | E15: 82 | F15: 0 | G15: 14 | H15: 0 | I15: 0 | J15: 87 | K15: 43 | L15: 56 | M15: 0 | N15: 10
A16: Leche fluida x litro | B16: =ROUNDUP(' AZUL 2'!B135,0) -> 63 | C16: 0 | D16: =ROUNDUP(' AZUL 2'!D135,0) -> 4 | E16: =ROUNDUP(' AZUL 2'!E135,0) -> 109 | F16: 0 | G16: =ROUNDUP(' AZUL 2'!G135,0) -> 19 | H16: 0 | I16: =ROUNDUP(' AZUL 2'!I135,0) -> 43 | J16: 0 | K16: =ROUNDUP(' AZUL 2'!K135,0) -> 57 | L16: 60 | M16: 5 | N16: 0
A17: Azucar kg | B17: =ROUNDUP(' AZUL 2'!B136,0) -> 2 | C17: =ROUNDUP(' AZUL 2'!C136,0) -> 2 | D17: 0 | E17: =ROUNDUP(' AZUL 2'!E136,0) -> 4 | F17: =ROUNDUP(' AZUL 2'!F136,0) -> 1 | G17: 2 | H17: 0 | I17: =ROUNDUP(' AZUL 2'!I136,0) -> 1 | J17: =ROUNDUP(' AZUL 2'!J136,0) -> 1 | K17: =ROUNDUP(' AZUL 2'!K136,0) -> 1 | L17: =ROUNDUP(' AZUL 2'!L136,0) -> 1 | M17: =ROUNDUP(' AZUL 2'!M136,0) -> 1 | N17: =ROUNDUP(' AZUL 2'!N136,0) -> 1
A18: Té en saquito x 25 u | B18: 0 | C18: 0 | D18: 0 | E18: =ROUNDUP(' AZUL 2'!E137,0) -> 10 | F18: 0 | G18: =ROUNDUP(' AZUL 2'!G137,0) -> 2 | H18: 0 | I18: 0 | J18: 0 | K18: 0 | L18: 0 | M18: =ROUNDUP(' AZUL 2'!M137,0) -> 1 | N18: 0
A19: Cacao en polvo x 360 g | B19: =ROUNDUP(' AZUL 2'!B138,0) -> 6 | C19: =ROUNDUP(' AZUL 2'!C138,0) -> 6 | D19: 0 | E19: =ROUNDUP(' AZUL 2'!E138,0) -> 10 | F19: 0 | G19: =ROUNDUP(' AZUL 2'!G138,0) -> 2 | H19: 0 | I19: =ROUNDUP(' AZUL 2'!I138,0) -> 4 | J19: =ROUNDUP(' AZUL 2'!J138,0) -> 9 | K19: 0 | L19: =ROUNDUP(' AZUL 2'!L138,0) -> 6 | M19: =ROUNDUP(' AZUL 2'!M138,0) -> 1 | N19: 0
A20: Dulce de leche por 400 gr | B20: =ROUNDUP(' AZUL 2'!B139,0) -> 8 | C20: 0 | D20: 0 | E20: =ROUNDUP(' AZUL 2'!E139,0) -> 13 | F20: =ROUNDUP(' AZUL 2'!F139,0) -> 7 | G20: =ROUNDUP(' AZUL 2'!G139,0) -> 3 | H20: 0 | I20: =ROUNDUP(' AZUL 2'!I139,0) -> 6 | J20: =ROUNDUP(' AZUL 2'!J139,0) -> 12 | K20: =ROUNDUP(' AZUL 2'!K139,0) -> 7 | L20: =ROUNDUP(' AZUL 2'!L139,0) -> 7 | M20: =ROUNDUP(' AZUL 2'!M139,0) -> 1 | N20: =ROUNDUP(' AZUL 2'!N139,0) -> 2
A21: Dulce de batata x kg | B21: 0 | C21: 0 | D21: 0 | E21: =ROUNDUP(' AZUL 2'!E140,0) -> 4 | F21: 0 | G21: =ROUNDUP(' AZUL 2'!G140,0) -> 1 | H21: 0 | I21: 0 | J21: 0 | K21: =ROUNDUP(' AZUL 2'!K140,0) -> 2 | L21: 0 | M21: =ROUNDUP(' AZUL 2'!M140,0) -> 1 | N21: =ROUNDUP(' AZUL 2'!N140,0) -> 1
A22: Queso cuartirolo cx kg | B22: =ROUNDUP(' AZUL 2'!B141,0) -> 3 | C22: =ROUNDUP(' AZUL 2'!C141,0) -> 0 | D22: 0 | E22: =ROUNDUP(' AZUL 2'!E141,0) -> 5 | F22: =ROUNDUP(' AZUL 2'!F141,0) -> 0 | G22: =ROUNDUP(' AZUL 2'!G141,0) -> 1 | H22: 0 | I22: =ROUNDUP(' AZUL 2'!I141,0) -> 0 | J22: =ROUNDUP(' AZUL 2'!J141,0) -> 5 | K22: =ROUNDUP(' AZUL 2'!K141,0) -> 3 | L22: =ROUNDUP(' AZUL 2'!L141,0) -> 3 | M22: =ROUNDUP(' AZUL 2'!M141,0) -> 0 | N22: =ROUNDUP(' AZUL 2'!N141,0) -> 1
A23: Aceite girasol por 900 cc | B23: 0 | C23: =ROUNDUP(' AZUL 2'!C142,0) -> 0 | D23: =ROUNDUP(' AZUL 2'!D142,0) -> 1 | E23: 1 | F23: =ROUNDUP(' AZUL 2'!F142,0) -> 0 | G23: =ROUNDUP(' AZUL 2'!G142,0) -> 1 | H23: =ROUNDUP(' AZUL 2'!H142,0) -> 0 | I23: =ROUNDUP(' AZUL 2'!I142,0) -> 0 | J23: =ROUNDUP(' AZUL 2'!J142,0) -> 3 | K23: =ROUNDUP(' AZUL 2'!K142,0) -> 2 | L23: 0 | M23: =ROUNDUP(' AZUL 2'!M142,0) -> 0 | N23: =ROUNDUP(' AZUL 2'!N142,0) -> 1
A24: Arroz 00000 por kg | B24: 0 | C24: =ROUNDUP(' AZUL 2'!C143,0) -> 0 | D24: 0 | E24: =ROUNDUP(' AZUL 2'!E143,0) -> 7 | F24: =ROUNDUP(' AZUL 2'!F143,0) -> 0 | G24: =ROUNDUP(' AZUL 2'!G143,0) -> 2 | H24: =ROUNDUP(' AZUL 2'!H143,0) -> 0 | I24: =ROUNDUP(' AZUL 2'!I143,0) -> 0 | J24: =ROUNDUP(' AZUL 2'!J143,0) -> 7 | K24: 0 | L24: 0 | M24: =ROUNDUP(' AZUL 2'!M143,0) -> 0 | N24: 0
A25: Arvejas x 340 gr Tetra Brik | B25: 0 | C25: =ROUNDUP(' AZUL 2'!C144,0) -> 0 | D25: =ROUNDUP(' AZUL 2'!D144,0) -> 0 | E25: =ROUNDUP(' AZUL 2'!E144,0) -> 0 | F25: =ROUNDUP(' AZUL 2'!F144,0) -> 0 | G25: =ROUNDUP(' AZUL 2'!G144,0) -> 0 | H25: =ROUNDUP(' AZUL 2'!H144,0) -> 0 | I25: =ROUNDUP(' AZUL 2'!I144,0) -> 0 | J25: =ROUNDUP(' AZUL 2'!J144,0) -> 0 | ... M25: =ROUNDUP(' AZUL 2'!M144,0) -> 0 | N25: 0
A26: Lentejas remojadas x 350 gr | B26: =ROUNDUP(' AZUL 2'!B145,0) -> 6 | C26: =ROUNDUP(' AZUL 2'!C145,0) -> 0 | D26: =ROUNDUP(' AZUL 2'!D145,0) -> 1 | E26: =ROUNDUP(' AZUL 2'!E145,0) -> 10 | F26: =ROUNDUP(' AZUL 2'!F145,0) -> 0 | G26: =ROUNDUP(' AZUL 2'!G145,0) -> 2 | H26: =ROUNDUP(' AZUL 2'!H145,0) -> 0 | I26: =ROUNDUP(' AZUL 2'!I145,0) -> 0 | ... M26: =ROUNDUP(' AZUL 2'!M145,0) -> 0 | N26: 0
A27: Pimenton x 25 gr | B27: =ROUNDUP(' AZUL 2'!B146,0) -> 0 | C27: =ROUNDUP(' AZUL 2'!C146,0) -> 0 | D27: =ROUNDUP(' AZUL 2'!D146,0) -> 0 | E27: =ROUNDUP(' AZUL 2'!E146,0) -> 0 | F27: =ROUNDUP(' AZUL 2'!F146,0) -> 0 | G27: =ROUNDUP(' AZUL 2'!G146,0) -> 0 | H27: =ROUNDUP(' AZUL 2'!H146,0) -> 0 | I27: =ROUNDUP(' AZUL 2'!I146,0) -> 0 | ... N27: =ROUNDUP(' AZUL 2'!N146,0) -> 0
A28: Oregano x 25 gr | B28: =ROUNDUP(' AZUL 2'!B147,0) -> 0 | C28: =ROUNDUP(' AZUL 2'!C147,0) -> 0 | D28: =ROUNDUP(' AZUL 2'!D147,0) -> 0 | E28: =ROUNDUP(' AZUL 2'!E147,0) -> 0 | F28: =ROUNDUP(' AZUL 2'!F147,0) -> 0 | G28: =ROUNDUP(' AZUL 2'!G147,0) -> 0 | H28: =ROUNDUP(' AZUL 2'!H147,0) -> 0 | I28: =ROUNDUP(' AZUL 2'!I147,0) -> 0 | ... N28: =ROUNDUP(' AZUL 2'!N147,0) -> 0
A29: Condimento para pizza x 25 gr | B29: =ROUNDUP(' AZUL 2'!B148,0) -> 3 | C29: =ROUNDUP(' AZUL 2'!C148,0) -> 0 | D29: 0 | E29: =ROUNDUP(' AZUL 2'!E148,0) -> 5 | F29: =ROUNDUP(' AZUL 2'!F148,0) -> 0 | G29: =ROUNDUP(' AZUL 2'!G148,0) -> 1 | H29: =ROUNDUP(' AZUL 2'!H148,0) -> 0 | I29: =ROUNDUP(' AZUL 2'!I148,0) -> 0 | J29: 0 | K29: 0 | L29: 0 | M29: =ROUNDUP(' AZUL 2'!M148,0) -> 0 | N29: 0
A30: Sal fina x 500 gr | B30: =ROUNDUP(' AZUL 2'!B149,0) -> 1 | C30: =ROUNDUP(' AZUL 2'!C149,0) -> 0 | D30: 0 | E30: =ROUNDUP(' AZUL 2'!E149,0) -> 1 | F30: =ROUNDUP(' AZUL 2'!F149,0) -> 0 | G30: =ROUNDUP(' AZUL 2'!G149,0) -> 1 | H30: =ROUNDUP(' AZUL 2'!H149,0) -> 0 | I30: =ROUNDUP(' AZUL 2'!I149,0) -> 0 | J30: =ROUNDUP(' AZUL 2'!J149,0) -> 1 | K30: =ROUNDUP(' AZUL 2'!K149,0) -> 1 | L30: =ROUNDUP(' AZUL 2'!L149,0) -> 1 | M30: =ROUNDUP(' AZUL 2'!M149,0) -> 0 | N30: 0
A31: Fideo tirabuzòn x 500 g | B31: 0 | C31: =ROUNDUP(' AZUL 2'!C150,0) -> 0 | D31: =ROUNDUP(' AZUL 2'!D150,0) -> 1 | E31: =ROUNDUP(' AZUL 2'!E150,0) -> 12 | F31: =ROUNDUP(' AZUL 2'!F150,0) -> 0 | G31: 3 | H31: =ROUNDUP(' AZUL 2'!H150,0) -> 0 | I31: =ROUNDUP(' AZUL 2'!I150,0) -> 0 | J31: =ROUNDUP(' AZUL 2'!J150,0) -> 13 | K31: 0 | L31: 0 | M31: =ROUNDUP(' AZUL 2'!M150,0) -> 0 | N31: 0
A32: Tomate triturado tetrabrik x 500g | B32: =ROUNDUP(' AZUL 2'!B151,0) -> 5 | C32: =ROUNDUP(' AZUL 2'!C151,0) -> 0 | D32: =ROUNDUP(' AZUL 2'!D151,0) -> 1 | E32: =ROUNDUP(' AZUL 2'!E151,0) -> 8 | F32: =ROUNDUP(' AZUL 2'!F151,0) -> 0 | G32: =ROUNDUP(' AZUL 2'!G151,0) -> 2 | H32: =ROUNDUP(' AZUL 2'!H151,0) -> 0 | I32: =ROUNDUP(' AZUL 2'!I151,0) -> 0 | ... N32: =ROUNDUP(' AZUL 2'!N151,0) -> 1
A33: Pan rallado x kg | B33: =ROUNDUP(' AZUL 2'!B152,0) -> 2 | C33: =ROUNDUP(' AZUL 2'!C152,0) -> 0 | D33: =ROUNDUP(' AZUL 2'!D152,0) -> 1 | E33: 0 | F33: =ROUNDUP(' AZUL 2'!F152,0) -> 0 | G33: =ROUNDUP(' AZUL 2'!G152,0) -> 1 | H33: =ROUNDUP(' AZUL 2'!H152,0) -> 0 | I33: =ROUNDUP(' AZUL 2'!I152,0) -> 0 | J33: =ROUNDUP(' AZUL 2'!J152,0) -> 4 | K33: 0 | L33: =ROUNDUP(' AZUL 2'!L152,0) -> 2 | M33: =ROUNDUP(' AZUL 2'!M152,0) -> 0 | N33: =ROUNDUP(' AZUL 2'!N152,0) -> 1
A34: Almidon de maiz x 500 g | B34: 0 | C34: =ROUNDUP(' AZUL 2'!C153,0) -> 0 | D34: =ROUNDUP(' AZUL 2'!D153,0) -> 1 | E34: =ROUNDUP(' AZUL 2'!E153,0) -> 1 | F34: =ROUNDUP(' AZUL 2'!F153,0) -> 0 | G34: =ROUNDUP(' AZUL 2'!G153,0) -> 1 | H34: =ROUNDUP(' AZUL 2'!H153,0) -> 0 | I34: =ROUNDUP(' AZUL 2'!I153,0) -> 0 | J34: =ROUNDUP(' AZUL 2'!J153,0) -> 1 | K34: 0 | L34: 0 | M34: =ROUNDUP(' AZUL 2'!M153,0) -> 0 | N34: 0
A35: Esencia de vainilla x 100 cc | B35: 0 | C35: =ROUNDUP(' AZUL 2'!C154,0) -> 0 | D35: =ROUNDUP(' AZUL 2'!D154,0) -> 0 | E35: =ROUNDUP(' AZUL 2'!E154,0) -> 0 | F35: =ROUNDUP(' AZUL 2'!F154,0) -> 0 | G35: =ROUNDUP(' AZUL 2'!G154,0) -> 0 | H35: =ROUNDUP(' AZUL 2'!H154,0) -> 0 | I35: =ROUNDUP(' AZUL 2'!I154,0) -> 0 | J35: =ROUNDUP(' AZUL 2'!J154,0) -> 0 | ... M35: =ROUNDUP(' AZUL 2'!M154,0) -> 0 | N35: 0
A36: Harina Leudante x kg | B36: =ROUNDUP(' AZUL 2'!B155,0) -> 3 | C36: =ROUNDUP(' AZUL 2'!C155,0) -> 0 | D36: =ROUNDUP(' AZUL 2'!D155,0) -> 1 | E36: =ROUNDUP(' AZUL 2'!E155,0) -> 5 | F36: =ROUNDUP(' AZUL 2'!F155,0) -> 0 | G36: =ROUNDUP(' AZUL 2'!G155,0) -> 1 | H36: =ROUNDUP(' AZUL 2'!H155,0) -> 0 | I36: =ROUNDUP(' AZUL 2'!I155,0) -> 0 | ... M36: =ROUNDUP(' AZUL 2'!M155,0) -> 0 | N36: 0
A37: Harina 000 x kg | B37: =ROUNDUP(' AZUL 2'!B156,0) -> 4 | C37: =ROUNDUP(' AZUL 2'!C156,0) -> 0 | D37: =ROUNDUP(' AZUL 2'!D156,0) -> 1 | E37: =ROUNDUP(' AZUL 2'!E156,0) -> 7 | F37: =ROUNDUP(' AZUL 2'!F156,0) -> 0 | G37: =ROUNDUP(' AZUL 2'!G156,0) -> 2 | H37: =ROUNDUP(' AZUL 2'!H156,0) -> 0 | I37: =ROUNDUP(' AZUL 2'!I156,0) -> 0 | ... M37: =ROUNDUP(' AZUL 2'!M156,0) -> 0 | N37: 0
A38: Levadura seca x 20 gr | B38: =ROUNDUP(' AZUL 2'!B157,0) -> 1 | C38: =ROUNDUP(' AZUL 2'!C157,0) -> 0 | D38: =ROUNDUP(' AZUL 2'!D157,0) -> 1 | E38: =ROUNDUP(' AZUL 2'!E157,0) -> 2 | F38: =ROUNDUP(' AZUL 2'!F157,0) -> 0 | G38: =ROUNDUP(' AZUL 2'!G157,0) -> 1 | H38: =ROUNDUP(' AZUL 2'!H157,0) -> 0 | I38: =ROUNDUP(' AZUL 2'!I157,0) -> 0 | ... N38: =ROUNDUP(' AZUL 2'!N157,0) -> 1
A39: GALLETAS MARINERA SIN SAL X 300 G | L39: 1
A40: LECHE DESLACTOSADA X L
B42: EP 26 | C42: EP 27 | D42: EP 33 | E42: EP36 JIR2 | F42: EP 37 | G42: EP38 JIR15 | H42: EP39 JIR10 | I42: EP 41 | J42: EP 43 | K42: EP50 JIR 13 | L42: EP 53 | M42: EP 55 | N42: EP57 JIR 11
B43: 49 | C43: 230 | D43: 19 | E43: 38 | F43: 26 | G43: 5 | H43: 5 | I43: 8 | J43: 8 | K43: 7 | L43: 10 | M43: 17 | N43: 9
B44: 40 | C44: 115 | D44: 0 | E44: 0 | F44: 13 | G44: 1 | H44: 0 | I44: 0 | J44: 0 | K44: 0 | L44: 0 | M44: 0 | N44: 3
A45: Leche fluida x litro | B45: 0 | C45: 0 | D45: 0 | E45: 15 | F45: =ROUNDUP(' AZUL 2'!F164,0) -> 18 | G45: 0 | H45: 0 | I45: =ROUNDUP(' AZUL 2'!I164,0) -> 5 | J45: =ROUNDUP(' AZUL 2'!J164,0) -> 5 | K45: 0 | L45: =ROUNDUP(' AZUL 2'!L164,0) -> 6 | M45: =ROUNDUP(' AZUL 2'!M164,0) -> 11 | N45: 0
A46: Azucar kg | B46: =ROUNDUP(' AZUL 2'!B165,0) -> 2 | C46: =ROUNDUP(' AZUL 2'!C165,0) -> 4 | D46: =ROUNDUP(' AZUL 2'!D165,0) -> 1 | E46: =ROUNDUP(' AZUL 2'!E165,0) -> 1 | F46: =ROUNDUP(' AZUL 2'!F165,0) -> 1 | G46: 0 | H46: 0 | I46: =ROUNDUP(' AZUL 2'!I165,0) -> 1 | J46: =ROUNDUP(' AZUL 2'!J165,0) -> 1 | K46: 0 | L46: 0 | M46: =ROUNDUP(' AZUL 2'!M165,0) -> 1 | N46: =ROUNDUP(' AZUL 2'!N165,0) -> 1
A47: Té en saquito x 25 u | B47: 0 | C47: 0 | D47: =ROUNDUP(' AZUL 2'!D166,0) -> 2 | E47: 2 | F47: =ROUNDUP(' AZUL 2'!F166,0) -> 2 | G47: 0 | H47: 0 | I47: 0 | J47: =ROUNDUP(' AZUL 2'!J166,0) -> 1 | K47: 0 | L47: 0 | M47: =ROUNDUP(' AZUL 2'!M166,0) -> 2 | N47: 0
A48: Cacao en polvo x 360 g | B48: =ROUNDUP(' AZUL 2'!B167,0) -> 3 | C48: 0 | D48: 0 | E48: 2 | F48: =ROUNDUP(' AZUL 2'!F167,0) -> 2 | G48: 0 | H48: 0 | I48: =ROUNDUP(' AZUL 2'!I167,0) -> 1 | J48: =ROUNDUP(' AZUL 2'!J167,0) -> 1 | K48: 0 | L48: 0 | M48: =ROUNDUP(' AZUL 2'!M167,0) -> 1 | N48: 0
...

Sheet OC CAR y PAN AZUL 2
A6: AZUL PERIODO REGULAR 2026
A7: ORDEN DE COMPRA
A8: FECHA:
A11: CARNE-
A12: PROVEEDOR ALVAREZ (LA SOÑADA) y FURIO 1° RENGLON -
B14: EP 1 | C14: EP 7 | D14: EP 9 | E14: EP 13 | F14: EP 14 | G14: EP 16 | H14: EP 17 | I14: EP 18 | J14: EP 19 | K14: EP 21 | L14: EP 22 | M14: EP24 JIR7 | N14: EP25 JIR 4
B15: 94 | C15: 101 | D15: 6 | E15: 164 | F15: 90 | G15: 28 | H15: 27 | I15: 71 | J15: 148 | K15: 86 | L15: 92 | M15: 13 | N15: 22
B16: 47 | C16: 0 | D16: 3 | E16: 82 | F16: 0 | G16: 14 | H16: 0 | I16: 0 | J16: 87 | K16: 43 | L16: 56 | M16: 0 | N16: 10
A17: PULPA DE CERDO fileteada por Kg. | B17: =ROUNDUP(' AZUL 2'!B286,0) -> 5 | C17: =ROUNDUP(' AZUL 2'!C286,0) -> 0 | D17: =ROUNDUP(' AZUL 2'!D286,0) -> 1 | E17: =ROUNDUP(' AZUL 2'!E286,0) -> 9 | F17: =ROUNDUP(' AZUL 2'!F286,0) -> 0 | G17: =ROUNDUP(' AZUL 2'!G286,0) -> 2 | H17: =ROUNDUP(' AZUL 2'!H286,0) -> 0 | I17: =ROUNDUP(' AZUL 2'!I286,0) -> 0 | ... N17: =ROUNDUP(' AZUL 2'!N286,0) -> 1
A18: POLLO por Kg. | B18: =ROUNDUP(' AZUL 2'!B287,0) -> 7 | C18: =ROUNDUP(' AZUL 2'!C287,0) -> 0 | D18: =ROUNDUP(' AZUL 2'!D287,0) -> 1 | E18: =ROUNDUP(' AZUL 2'!E287,0) -> 12 | F18: =ROUNDUP(' AZUL 2'!F287,0) -> 0 | G18: 3 | H18: =ROUNDUP(' AZUL 2'!H287,0) -> 0 | I18: =ROUNDUP(' AZUL 2'!I287,0) -> 0 | J18: =ROUNDUP(' AZUL 2'!J287,0) -> 12 | K18: =ROUNDUP(' AZUL 2'!K287,0) -> 6 | L18: =ROUNDUP(' AZUL 2'!L287,0) -> 8 | M18: =ROUNDUP(' AZUL 2'!M287,0) -> 0 | N18: =ROUNDUP(' AZUL 2'!N287,0) -> 2
A19: NALGA CERDO fileteada para milanesa por Kg. | B19: =ROUNDUP(' AZUL 2'!B288,0) -> 5 | C19: =ROUNDUP(' AZUL 2'!C288,0) -> 0 | D19: =ROUNDUP(' AZUL 2'!D288,0) -> 1 | E19: =ROUNDUP(' AZUL 2'!E288,0) -> 9 | F19: =ROUNDUP(' AZUL 2'!F288,0) -> 0 | G19: =ROUNDUP(' AZUL 2'!G288,0) -> 2 | H19: =ROUNDUP(' AZUL 2'!H288,0) -> 0 | I19: =ROUNDUP(' AZUL 2'!I288,0) -> 0 | ... N19: =ROUNDUP(' AZUL 2'!N288,0) -> 1
B21: EP 26 | C21: EP 27 | D21: EP 33 | E21: EP36 JIR2 | F21: EP 37 | G21: EP38 JIR15 | H21: EP39 JIR10 | I21: EP 41 | J21: EP 43 | K21: EP50 JIR 13 | L21: EP 53 | M21: EP 55 | N21: EP57 JIR 11
B22: 49 | C22: 230 | D22: 19 | E22: 38 | F22: 26 | G22: 5 | H22: 5 | I22: 8 | J22: 8 | K22: 7 | L22: 10 | M22: 17 | N22: 9
B23: 40 | C23: 115 | D23: 0 | E23: 0 | F23: 13 | G23: 1 | H23: 0 | I23: 0 | J23: 0 | K23: 0 | L23: 0 | M23: 0 | N23: 3
A24: PULPA DE CERDO fileteada por Kg. | B24: =ROUNDUP(' AZUL 2'!B293,0) -> 4 | C24: =ROUNDUP(' AZUL 2'!C293,0) -> 12 | D24: =ROUNDUP(' AZUL 2'!D293,0) -> 0 | E24: =ROUNDUP(' AZUL 2'!E293,0) -> 0 | F24: =ROUNDUP(' AZUL 2'!F293,0) -> 2 | G24: 0 | H24: =ROUNDUP(' AZUL 2'!H293,0) -> 0 | I24: =ROUNDUP(' AZUL 2'!I293,0) -> 0 | J24: =ROUNDUP(' AZUL 2'!J293,0) -> 0 | K24: =ROUNDUP(' AZUL 2'!K293,0) -> 0 | L24: =ROUNDUP(' AZUL 2'!L293,0) -> 0 | M24: =ROUNDUP(' AZUL 2'!M293,0) -> 0 | N24: =ROUNDUP(' AZUL 2'!N293,0) -> 1
A25: POLLO por Kg. | B25: =ROUNDUP(' AZUL 2'!B294,0) -> 6 | C25: =ROUNDUP(' AZUL 2'!C294,0) -> 16 | D25: =ROUNDUP(' AZUL 2'!D294,0) -> 0 | E25: =ROUNDUP(' AZUL 2'!E294,0) -> 0 | F25: =ROUNDUP(' AZUL 2'!F294,0) -> 2 | G25: 0 | H25: =ROUNDUP(' AZUL 2'!H294,0) -> 0 | I25: =ROUNDUP(' AZUL 2'!I294,0) -> 0 | J25: =ROUNDUP(' AZUL 2'!J294,0) -> 0 | K25: =ROUNDUP(' AZUL 2'!K294,0) -> 0 | L25: =ROUNDUP(' AZUL 2'!L294,0) -> 0 | M25: =ROUNDUP(' AZUL 2'!M294,0) -> 0 | N25: =ROUNDUP(' AZUL 2'!N294,0) -> 1
A26: NALGA CERDO fileteada para milanesa por Kg. | B26: =ROUNDUP(' AZUL 2'!B295,0) -> 4 | C26: =ROUNDUP(' AZUL 2'!C295,0) -> 12 | D26: =ROUNDUP(' AZUL 2'!D295,0) -> 0 | E26: =ROUNDUP(' AZUL 2'!E295,0) -> 0 | F26: =ROUNDUP(' AZUL 2'!F295,0) -> 2 | G26: 0 | H26: =ROUNDUP(' AZUL 2'!H295,0) -> 0 | I26: =ROUNDUP(' AZUL 2'!I295,0) -> 0 | J26: =ROUNDUP(' AZUL 2'!J295,0) -> 0 | K26: =ROUNDUP(' AZUL 2'!K295,0) -> 0 | L26: =ROUNDUP(' AZUL 2'!L295,0) -> 0 | M26: =ROUNDUP(' AZUL 2'!M295,0) -> 0 | N26: =ROUNDUP(' AZUL 2'!N295,0) -> 1
B28: EP 62 | C28: EP 64 | D28: EP 65 | E28: EP 66 | F28: Ins. San | G28: EES 7 | H28: EES 8 | I28: EES 9 | J28: EES 9 | K28: EES 10 | L28: EES 11 | M28: EES 11 | N28: EES 12
F29: PRIM | I29: EP 7 | J29: EP 36 | L29: EP 18 | M29: EP 14 | N29: EP 27
B30: 167 | C30: 148 | D30: 7 | E30: 178 | F30: 108 | G30: 35 | H30: 149 | I30: 99 | J30: 33 | K30: 150 | L30: 123 | M30: 78 | N30: 170
B31: 60 | C31: 100 | D31: 0 | E31: 89 | F31: 0 | G31: 0 | H31: 149 | I31: 0 | J31: 0 | K31: 95 | L31: 0 | M31: 0 | N31: 70
A32: PULPA DE CERDO fileteada por Kg. | B32: =ROUNDUP(' AZUL 2'!B301,0) -> 6 | C32: =ROUNDUP(' AZUL 2'!C301,0) -> 10 | D32: =ROUNDUP(' AZUL 2'!D301,0) -> 0 | E32: =ROUNDUP(' AZUL 2'!E301,0) -> 9 | F32: =ROUNDUP(' AZUL 2'!F301,0) -> 0 | G32: =ROUNDUP(' AZUL 2'!G301,0) -> 0 | H32: =ROUNDUP(' AZUL 2'!H301,0) -> 15 | I32: =ROUNDUP(' AZUL 2'!I301,0) -> 0 | ... N32: =ROUNDUP(' AZUL 2'!N301,0) -> 7
A33: POLLO por Kg. | B33: 7 | C33: =ROUNDUP(' AZUL 2'!C302,0) -> 14 | D33: =ROUNDUP(' AZUL 2'!D302,0) -> 0 | E33: =ROUNDUP(' AZUL 2'!E302,0) -> 12 | F33: =ROUNDUP(' AZUL 2'!F302,0) -> 0 | G33: =ROUNDUP(' AZUL 2'!G302,0) -> 0 | H33: =ROUNDUP(' AZUL 2'!H302,0) -> 21 | I33: =ROUNDUP(' AZUL 2'!I302,0) -> 0 | J33: =ROUNDUP(' AZUL 2'!J302,0) -> 0 | ... N33: =ROUNDUP(' AZUL 2'!N302,0) -> 10
A34: NALGA CERDO fileteada para milanesa por Kg. | B34: =ROUNDUP(' AZUL 2'!B303,0) -> 6 | C34: =ROUNDUP(' AZUL 2'!C303,0) -> 10 | D34: =ROUNDUP(' AZUL 2'!D303,0) -> 0 | E34: =ROUNDUP(' AZUL 2'!E303,0) -> 9 | F34: =ROUNDUP(' AZUL 2'!F303,0) -> 0 | G34: =ROUNDUP(' AZUL 2'!G303,0) -> 0 | H34: =ROUNDUP(' AZUL 2'!H303,0) -> 15 | I34: =ROUNDUP(' AZUL 2'!I303,0) -> 0 | ... N34: =ROUNDUP(' AZUL 2'!N303,0) -> 7
B36: EES 12 | C36: EEST 1 | D36: EEST 2 | E36: SAN FCO | F36: CEPT 31 | G36: CFI 1 | H36: 502 | I36: 503 | J36: 504 | K36: 505 | L36: VIVENCIAS | M36: CADRAL | N36: CEC 802
B37: EP 26 | E37: SEC
B38: 68 | C38: 566 | D38: 850 | E38: 121 | F38: 100 | G38: 108 | H38: 124 | I38: 46 | J38: 50 | K38: 104 | L38: 60 | M38: 42 | N38: 103
B39: 68 | C39: 160 | D39: 0 | E39: 0 | F39: 100 | G39: 54 | H39: 62 | I39: 23 | J39: 25 | K39: 52 | L39: 30 | M39: 19 | N39: 103
A40: PULPA DE CERDO fileteada por Kg. | B40: =ROUNDUP(' AZUL 2'!B309,0) -> 7 | C40: =ROUNDUP(' AZUL 2'!C309,0) -> 16 | D40: =ROUNDUP(' AZUL 2'!D309,0) -> 0 | E40: =ROUNDUP(' AZUL 2'!E309,0) -> 0 | F40: =ROUNDUP(' AZUL 2'!F309,0) -> 10 | G40: =ROUNDUP(' AZUL 2'!G309,0) -> 6 | H40: =ROUNDUP(' AZUL 2'!H309,0) -> 7 | I40: =ROUNDUP(' AZUL 2'!I309,0) -> 3 | ... N40: =ROUNDUP(' AZUL 2'!N309,0) -> 11
A41: POLLO por Kg. | B41: =ROUNDUP(' AZUL 2'!B310,0) -> 10 | C41: =ROUNDUP(' AZUL 2'!C310,0) -> 22 | D41: =ROUNDUP(' AZUL 2'!D310,0) -> 0 | E41: =ROUNDUP(' AZUL 2'!E310,0) -> 0 | F41: =ROUNDUP(' AZUL 2'!F310,0) -> 14 | G41: =ROUNDUP(' AZUL 2'!G310,0) -> 8 | H41: =ROUNDUP(' AZUL 2'!H310,0) -> 9 | I41: =ROUNDUP(' AZUL 2'!I310,0) -> 4 | ... N41: =ROUNDUP(' AZUL 2'!N310,0) -> 14
A42: NALGA CERDO fileteada para milanesa por Kg. | B42: =ROUNDUP(' AZUL 2'!B311,0) -> 7 | C42: =ROUNDUP(' AZUL 2'!C311,0) -> 16 | D42: =ROUNDUP(' AZUL 2'!D311,0) -> 0 | E42: =ROUNDUP(' AZUL 2'!E311,0) -> 0 | F42: =ROUNDUP(' AZUL 2'!F311,0) -> 10 | G42: =ROUNDUP(' AZUL 2'!G311,0) -> 6 | H42: =ROUNDUP(' AZUL 2'!H311,0) -> 7 | I42: =ROUNDUP(' AZUL 2'!I311,0) -> 3 | ... N42: =ROUNDUP(' AZUL 2'!N311,0) -> 11
B44: JI 901 | C44: JI 902 | D44: JI 905 | E44: JI 906 | F44: JI 907 | G44: JI 908 | H44: JI 909 | I44: JI 910 | J44: JI 912 | K44: JI 913 | L44: JI 914 | M44: JI 915 | N44: JI 916 | O44: JI 917 | P44: JI 918 | Q44: JI 919
B45: 160 | C45: 80 | D45: 156 | E45: 97 | F45: 2 | G45: 78 | H45: 69 | I45: 61 | J45: 131 | K45: 75 | L45: 66 | M45: 80 | N45: 71 | O45: 69 | P45: 42 | Q45: 70
B46: 0 | C46: 0 | D46: 0 | E46: 0 | F46: 0 | G46: 0 | H46: 0 | I46: 0 | J46: 40 | K46: 0 | L46: 0 | M46: 0 | N46: 0 | O46: 0 | P46: 0 | Q46: 0
A47: PULPA DE CERDO fileteada por Kg. | B47: =ROUNDUP(' AZUL 2'!B316,0) -> 0 | C47: =ROUNDUP(' AZUL 2'!C316,0) -> 0 | D47: =ROUNDUP(' AZUL 2'!D316,0) -> 0 | E47: =ROUNDUP(' AZUL 2'!E316,0) -> 0 | F47: =ROUNDUP(' AZUL 2'!F316,0) -> 0 | G47: =ROUNDUP(' AZUL 2'!G316,0) -> 0 | H47: =ROUNDUP(' AZUL 2'!H316,0) -> 0 | I47: =ROUNDUP(' AZUL 2'!I316,0) -> 0 | ... Q47: =ROUNDUP(' AZUL 2'!Q316,0) -> 0
A48: POLLO por Kg. | B48: =ROUNDUP(' AZUL 2'!B317,0) -> 0 | C48: =ROUNDUP(' AZUL 2'!C317,0) -> 0 | D48: =ROUNDUP(' AZUL 2'!D317,0) -> 0 | E48: =ROUNDUP(' AZUL 2'!E317,0) -> 0 | F48: =ROUNDUP(' AZUL 2'!F317,0) -> 0 | G48: =ROUNDUP(' AZUL 2'!G317,0) -> 0 | H48: =ROUNDUP(' AZUL 2'!H317,0) -> 0 | I48: =ROUNDUP(' AZUL 2'!I317,0) -> 0 | ... Q48: =ROUNDUP(' AZUL 2'!Q317,0) -> 0
A49: NALGA CERDO fileteada para milanesa por Kg. | B49: =ROUNDUP(' AZUL 2'!B318,0) -> 0 | C49: =ROUNDUP(' AZUL 2'!C318,0) -> 0 | D49: =ROUNDUP(' AZUL 2'!D318,0) -> 0 | E49: =ROUNDUP(' AZUL 2'!E318,0) -> 0 | F49: =ROUNDUP(' AZUL 2'!F318,0) -> 0 | G49: =ROUNDUP(' AZUL 2'!G318,0) -> 0 | H49: =ROUNDUP(' AZUL 2'!H318,0) -> 0 | I49: =ROUNDUP(' AZUL 2'!I318,0) -> 0 | ... Q49: =ROUNDUP(' AZUL 2'!Q318,0) -> 0
H51: PATIOS
A52: PAN | H52: ABIERTOS
A53: PROVEEDOR TESTA | H53: 8 KG POR
...

Sheet CACHARI 2
A7: CACHARI PERIODO REGULAR 2026
A8: ORDEN DE COMPRA
B9: FECHA:
A11: FRUTAS Y VERDURAS:
A12: PROVEEDOR: CAPPUCCIO LUIS-
B13: J904 | C13: EP4 | D13: EP5+JIR 5 | E13: EP6 | F13: EP23 | G13: EP29 | H13: EP31 | I13: EP32 | J13: EP34 | K13: EP44 | L13: EP59 | M13: CEC801 | N13: EEE506 | O13: EES2 | P13: TOTAL
A14: DMC | B14: 111 | C14: 6 | D14: 5 | E14: 35 | F14: 123 | G14: 3 | H14: 3 | I14: 5 | J14: 4 | K14: 4 | L14: 12 | M14: 130 | N14: 24 | O14: 171 | P14: =SUM(B14:O14) -> 636
A15: COM | B15: 0 | C15: 0 | D15: 0 | E15: 0 | F15: 0 | G15: 0 | H15: 0 | I15: 2 | J15: 0 | K15: 0 | L15: 6 | M15: 130 | N15: 12 | O15: 0 | P15: =SUM(B15:O15) -> 150 | Q15: PRECIO | R15: PESOS POR PRODUCTO
A16: MANZANA | B16: =PRODUCT(SEMANAL!D6,B14)/1000+PRODUCT(SEMANAL!B6,B15)/1000 -> 13.875 | C16: =PRODUCT(SEMANAL!D6,C$14)/1000+PRODUCT(SEMANAL!B6,C$15)/1000 -> 0.75 | D16: =PRODUCT(SEMANAL!D6,D$14)/1000+PRODUCT(SEMANAL!B6,D$15)/1000 -> 0.625 | E16: =PRODUCT(SEMANAL!D6,E$14)/1000+PRODUCT(SEMANAL!B6,E$15)/1000 -> 4.375 | F16: =PRODUCT(SEMANAL!D6,F$14)/1000+PRODUCT(SEMANAL!B6,F$15)/1000 -> 15.375 | G16: =PRODUCT(SEMANAL!D6,G$14)/1000+PRODUCT(SEMANAL!B6,G$15)/1000 -> 0.375 | H16: =PRODUCT(SEMANAL!D6,H$14)/1000+PRODUCT(SEMANAL!B6,H$15)/1000 -> 0.375 | I16: =PRODUCT(SEMANAL!D6,I$14)/1000+PRODUCT(SEMANAL!B6,I$15)/1000 -> 0.865 | J16: =PRODUCT(SEMANAL!D6,J$14)/1000+PRODUCT(SEMANAL!B6,J$15)/1000 -> 0.5 | K16: =PRODUCT(SEMANAL!D6,K$14)/1000+PRODUCT(SEMANAL!B6,K$15)/1000 -> 0.5 | L16: =PRODUCT(SEMANAL!D6,L$14)/1000+PRODUCT(SEMANAL!B6,L$15)/1000 -> 2.22 | M16: =PRODUCT(SEMANAL!D6,M$14)/1000+PRODUCT(SEMANAL!B6,M$15)/1000 -> 31.85 | N16: =PRODUCT(SEMANAL!D6,N$14)/1000+PRODUCT(SEMANAL!B6,N$15)/1000 -> 4.44 | O16: =PRODUCT(SEMANAL!D6,O$14)/1000+PRODUCT(SEMANAL!B6,O$15)/1000 -> 21.375 | P16: =SUM('OC CACHARI 2'!B16:O16) -> 72 | Q16: 2950 | R16: =PRODUCT(P16:Q16) -> 212400
A17: BANANA | B17: =PRODUCT(SEMANAL!D7,B14)/1000+PRODUCT(SEMANAL!B7,B15)/1000 -> 0 | C17: =PRODUCT(SEMANAL!D7,C$14)/1000+PRODUCT(SEMANAL!B7,C$15)/1000 -> 0 | D17: =PRODUCT(SEMANAL!D7,D$14)/1000+PRODUCT(SEMANAL!B7,D$15)/1000 -> 0 | E17: =PRODUCT(SEMANAL!D7,E$14)/1000+PRODUCT(SEMANAL!B7,E$15)/1000 -> 0 | F17: =PRODUCT(SEMANAL!D7,F$14)/1000+PRODUCT(SEMANAL!B7,F$15)/1000 -> 0 | G17: =PRODUCT(SEMANAL!D7,G$14)/1000+PRODUCT(SEMANAL!B7,G$15)/1000 -> 0 | H17: =PRODUCT(SEMANAL!D7,H$14)/1000+PRODUCT(SEMANAL!B7,H$15)/1000 -> 0 | I17: =PRODUCT(SEMANAL!D7,I$14)/1000+PRODUCT(SEMANAL!B7,I$15)/1000 -> 0.24 | J17: =PRODUCT(SEMANAL!D7,J$14)/1000+PRODUCT(SEMANAL!B7,J$15)/1000 -> 0 | K17: =PRODUCT(SEMANAL!D7,K$14)/1000+PRODUCT(SEMANAL!B7,K$15)/1000 -> 0 | L17: =PRODUCT(SEMANAL!D7,L$14)/1000+PRODUCT(SEMANAL!B7,L$15)/1000 -> 0.72 | M17: =PRODUCT(SEMANAL!D7,M$14)/1000+PRODUCT(SEMANAL!B7,M$15)/1000 -> 15.6 | N17: =PRODUCT(SEMANAL!D7,N$14)/1000+PRODUCT(SEMANAL!B7,N$15)/1000 -> 1.44 | O17: =PRODUCT(SEMANAL!D7,O$14)/1000+PRODUCT(SEMANAL!B7,O$15)/1000 -> 0 | P17: =SUM('OC CACHARI 2'!B17:O17) -> 20 | Q17: 3490 | R17: =PRODUCT(P17:Q17) -> 69800
A18: NARANJA O MANDARINA | B18: =PRODUCT(SEMANAL!D8,B$14)/1000+PRODUCT(SEMANAL!B8,B$15)/1000 -> 27.75 | C18: =PRODUCT(SEMANAL!D8,C$14)/1000+PRODUCT(SEMANAL!B8,C$15)/1000 -> 1.5 | D18: =PRODUCT(SEMANAL!D8,D$14)/1000+PRODUCT(SEMANAL!B8,D$15)/1000 -> 1.25 | E18: =PRODUCT(SEMANAL!D8,E$14)/1000+PRODUCT(SEMANAL!B8,E$15)/1000 -> 8.75 | F18: =PRODUCT(SEMANAL!D8,F$14)/1000+PRODUCT(SEMANAL!B8,F$15)/1000 -> 30.75 | G18: =PRODUCT(SEMANAL!D8,G$14)/1000+PRODUCT(SEMANAL!B8,G$15)/1000 -> 0.75 | H18: =PRODUCT(SEMANAL!D8,H$14)/1000+PRODUCT(SEMANAL!B8,H$15)/1000 -> 0.75 | I18: =PRODUCT(SEMANAL!D8,I$14)/1000+PRODUCT(SEMANAL!B8,I$15)/1000 -> 1.73 | J18: =PRODUCT(SEMANAL!D8,J$14)/1000+PRODUCT(SEMANAL!B8,J$15)/1000 -> 1 | K18: =PRODUCT(SEMANAL!D8,K$14)/1000+PRODUCT(SEMANAL!B8,K$15)/1000 -> 1 | L18: =PRODUCT(SEMANAL!D8,L$14)/1000+PRODUCT(SEMANAL!B8,L$15)/1000 -> 4.44 | M18: =PRODUCT(SEMANAL!D8,M$14)/1000+PRODUCT(SEMANAL!B8,M$15)/1000 -> 63.7 | N18: =PRODUCT(SEMANAL!D8,N$14)/1000+PRODUCT(SEMANAL!B8,N$15)/1000 -> 8.88 | O18: =PRODUCT(SEMANAL!D8,O$14)/1000+PRODUCT(SEMANAL!B8,O$15)/1000 -> 42.75 | P18: =SUM('OC CACHARI 2'!B18:O18) -> 135 | Q18: 1990 | R18: =PRODUCT(P18:Q18) -> 268650
